Workbook

Sheet MASTER-2025
A1: DONOR | B1: {KG DECREASE IN THE MONTH} | C1: {KG DONATED IN THE MONTH} | D1: {KG YOU PROFIT IN THE MONTH} | E1: {FEED FORMULA % USED} | F1: {FOOD FORMULA % MERMA} | G1: {FORMULA CONVERSION TO FOOD PLATES} | H1: SIN AREA Obs/PRO | I1: NO ASSIGNED KG AREA | J1: SIN AREA BENEFICIARIOS | K1: P CENTRO Obs/PRO | L1: P CENTRO KG ASIGNADOS | M1: P CENTRO BENEFICIARIOS | N1: ESTE Obs/PRO | O1: ESTE KG ASIGNADOS | P1: ESTE BENEFICIARIOS | Q1: NORTE Obs/PRO | R1: NORTE KG ASIGNADOS | S1: NORTE BENEFICIARIOS | T1: SAN MIGUELITO Obs/PRO | U1: SAN MIGUELITO KG ASIGNADOS | V1: SAN MIGUELITO BENEFICIARIOS | W1: OESTE Obs/PRO | X1: OESTE KG ASIGNADOS | Y1: OESTE BENEFICIARIOS | Z1: COCLE Obs/PRO | AA1: COCLE KG ASIGNADOS | AB1: COCLE BENEFICIARIOS | AC1: COLON Obs/PRO | AD1: COLON KG ASIGNADOS | AE1: COLON BENEFICIARIOS | AF1: DARIÉN Obs/PRO | AG1: DARIÉN KG ASIGNADOS | AH1: DARIÉN BENEFICIARIOS | AI1: HERRERA Obs/PRO | AJ1: HERRERA KG ASIGNADOS | AK1: HERRERA BENEFICIARIOS | AL1: LOS SANTOS Obs/PRO | AM1: LOS SANTOS KG ASIGNADOS | AN1: LOS SANTOS BENEFICIARIOS | AO1: VERAGUAS Obs/PRO | AP1: VERAGUAS KG ASIGNADOS | AQ1: VERAGUAS BENEFICIARIOS | AR1: CHIRIQUI Obs/PRO | AS1: CHIRIQUI KG ASIGNADOS | AT1: CHIRIQUI BENEFICIARIOS | AU1: BOCAS Obs/PRO | AV1: BOCAS KG ASIGNADOS | AW1: BOCAS BENEFICIARIOS | AX1: Comarca Ngabe Bugle Obs/PRO | AY1: Comarca Ngabe Bugle KG ASIGNADOS | AZ1: Comarca Ngabe Bugle BENEFICIARIOS | BA1: Total Obs/PRO | BB1: Total KG ASIGNADOS | BC1: Total_Prov_Pma | BD1: Total BENEFICIARIOS | BE1: Sin Edad | BF1: Niños 0-5 | BG1: Niños 6-10 | BH1: Niños 11-18 | BI1: Total NIÑOS | BJ1: Total ADULTOS | BK1: Benefeciarios en Total | BL1: OB_Ene | BM1: OB_Feb | BN1: OB_Mar | BO1: OB_Abr | BP1: OB_May | BQ1: OB_Jun | BR1: OB_Jul | BS1: OB_Ago | BT1: OB_Sep | BU1: OB_Oct | BV1: OB_Nov | BW1: OB_Dic | BX1: OB_Total | BY1: Kilos_Ene | BZ1: Kilos_Feb | CA1: Kilos_Mar | CB1: Kilos_Abr | CC1: Kilos_May | CD1: Kilos_Jun | CE1: Kilos_Jul | CF1: Kilos_Ago | CG1: Kilos_Sep | CH1: Kilos_Oct | CI1: Kilos_Nov | CJ1: Kilos_Dic | CK1: Kilos_Total | CL1: Poblacion_Ene | CM1: Poblacion_Feb | CN1: Poblacion_Mar | CO1: Poblacion_Abr | CP1: Poblacion_May | CQ1: Poblacion_Jun | CR1: Poblacion_Jul | CS1: Poblacion_Ago | CT1: Poblacion_Sep | CU1: Poblacion_Oct | CV1: Poblacion_Nov | CW1: Poblacion_Dic | CX1: Poblacion_Total | CY1: Contacto principal | CZ1: Correo Electrónico | DA1: Telefono | DB1: File Name
A2: FEDURO AGENCIES | B2: =INT(IFERROR(VLOOKUP(A2,'[1]Donor Summary'!C:F,3,0),0)) -> 0 | C2: =INT(ROUND(IFERROR(VLOOKUP(A2,'[1]Donor Summary'!C:F,4,0),0),1)) -> 0 | D2: =INT(ROUND(C2-B2,1)) -> 0 | E2: =IF(A2=0,"",TEXT((IFERROR(D2/C2,0)),"0.00%")) -> 0.00% | F2: =IF(A2=0,"",TEXT((IFERROR(B2/C2,0)),"0.0%")) -> 0.0% | G2: =INT(D2*3) -> 0 | I2: =IFERROR(VLOOKUP(A2,'[1]Lot All by Part'!T:Y,6,0),0) -> 0 | K2: =IFERROR(VLOOKUP($A2,'[1]Donor-Served OBs'!A:N,3,0),0) -> 0 | L2: =ROUNDUP(IF(A2=0,0,IFERROR(VLOOKUP($A2,'[1]Donor''s Assigned Kilos'!A:O,3,0),0)),0) -> 0 | M2: =IF(A2=0,0,IFERROR(SUMIFS([1]Population!M:M,[1]Population!J:J,'MASTER-2025'!A2),0)) -> 0 | N2: =IFERROR(VLOOKUP($A2,'[1]Donor-Served OBs'!A:N,4,0),0) -> 0 | O2: =ROUNDUP(IF(A2=0,0,IFERROR(VLOOKUP($A2,'[1]Donor''s Assigned Kilos'!A:O,4,0),0)),0) -> 0 | P2: =IF(A2=0,0,IFERROR(SUMIFS([1]Population!N:N,[1]Population!J:J,'MASTER-2025'!A2),0)) -> 0 | Q2: =IFERROR(VLOOKUP($A2,'[1]Donor-Served OBs'!A:N,2,0),0) -> 0 | R2: =ROUNDUP(ROUND(IF(A2=0,0,IFERROR(VLOOKUP($A2,'[1]Donor''s Assigned Kilos'!A:O,9,0),0)),1),0) -> 0 | S2: =IF(A2=0,0,IFERROR(SUMIFS([1]Population!S:S,[1]Population!J:J,'MASTER-2025'!A2),0)) -> 0 | T2: =IFERROR(VLOOKUP($A2,'[1]Donor-Served OBs'!A:N,12,0),0) -> 0 | U2: =ROUNDUP(IF(A2=0,0,IF(A2=0,0,IFERROR(VLOOKUP($A2,'[1]Donor''s Assigned Kilos'!A:O,7,0),0))),0) -> 0 | V2: =IF(A2=0,0,IFERROR(SUMIFS([1]Population!Q:Q,[1]Population!J:J,'MASTER-2025'!A2),0)) -> 0 | W2: =IFERROR(VLOOKUP($A2,'[1]Donor-Served OBs'!A:N,10,0),0) -> 0 | X2: =ROUNDUP(IF(A2=0,0,IFERROR(VLOOKUP($A2,'[1]Donor''s Assigned Kilos'!A:N,5,0),0)),0) -> 0 | Y2: =IF(A2=0,0,IFERROR(SUMIFS([1]Population!O:O,[1]Population!J:J,'MASTER-2025'!A2),0)) -> 0 | Z2: =IFERROR(VLOOKUP($A2,'[1]Donor-Served OBs'!A:N,6,0),0) -> 0 | AA2: =ROUNDUP(IF(A2=0,0,IFERROR(VLOOKUP($A2,'[1]Donor''s Assigned Kilos'!A:N,11,0),0)),0) -> 0 | AB2: =IF(A2=0,0,IFERROR(SUMIFS([1]Population!U:U,[1]Population!J:J,'MASTER-2025'!A2),0)) -> 0 | AC2: =IFERROR(VLOOKUP($A2,'[1]Donor-Served OBs'!A:N,7,0),0) -> 0 | AD2: =ROUNDUP(IF(A2=0,0,IFERROR(VLOOKUP($A2,'[1]Donor''s Assigned Kilos'!A:N,8,0),0)),0) -> 0 | AE2: =IF(A2=0,0,IFERROR(SUMIFS([1]Population!R:R,[1]Population!J:J,'MASTER-2025'!A2),0)) -> 0 | AF2: =IFERROR(VLOOKUP($A2,'[1]Donor-Served OBs'!A:N,8,0),0) -> 0 | AG2: =ROUNDUP(IF(A2=0,0,IFERROR(VLOOKUP($A2,'[1]Donor''s Assigned Kilos'!A:N,6,0),0)),0) -> 0 | AH2: =IF(A2=0,0,IFERROR(SUMIFS([1]Population!P:P,[1]Population!J:J,'MASTER-2025'!A2),0)) -> 0 | AI2: =IFERROR(VLOOKUP($A2,'[1]Donor-Served OBs'!A:N,9,0),0) -> 0 | AJ2: =ROUNDUP(IF(A2=0,0,IFERROR(VLOOKUP($A2,'[1]Donor''s Assigned Kilos'!A:N,12,0),0)),0) -> 0 | AK2: =IF(A2=0,0,IFERROR(SUMIFS([1]Population!V:V,[1]Population!J:J,'MASTER-2025'!A2),0)) -> 0 | AL2: =IFERROR(VLOOKUP($A2,'[1]Donor-Served OBs'!A:N,16,0),0) -> 0 | AM2: =ROUNDUP(IF(A2=0,0,IFERROR(VLOOKUP($A2,'[1]Donor''s Assigned Kilos'!A:O,16,0),0)),0) -> 0 | AN2: =IF(A2=0,0,IFERROR(SUMIFS([1]Population!Z:Z,[1]Population!J:J,'MASTER-2025'!A2),0)) -> 0 | AO2: =IFERROR(VLOOKUP($A2,'[1]Donor-Served OBs'!A:N,11,0),0) -> 0 | AP2: =ROUNDUP(IF(A2=0,0,IFERROR(VLOOKUP($A2,'[1]Donor''s Assigned Kilos'!A:N,13,0),0)),0) -> 0 | AQ2: =IF(A2=0,0,IFERROR(SUMIFS([1]Population!W:W,[1]Population!J:J,'MASTER-2025'!A2),0)) -> 0 | AR2: =IFERROR(VLOOKUP($A2,'[1]Donor-Served OBs'!A:N,5,0),0) -> 0 | AS2: =ROUNDUP(IF(A2=0,0,IFERROR(VLOOKUP($A2,'[1]Donor''s Assigned Kilos'!A:N,10,0),0)),0) -> 0 | AT2: =IF(A2=0,0,IFERROR(SUMIFS([1]Population!T:T,[1]Population!J:J,'MASTER-2025'!A2),0)) -> 0 | AU2: =IFERROR(VLOOKUP($A2,'[1]Donor-Served OBs'!A:N,13,0),0) -> 0 | AV2: =ROUNDUP(IF(A2=0,0,IFERROR(VLOOKUP($A2,'[1]Donor''s Assigned Kilos'!A:N,14,0),0)),0) -> 0 | AW2: =IF(A2=0,0,IFERROR(SUMIFS([1]Population!X:X,[1]Population!J:J,'MASTER-2025'!A2),0)) -> 0 | AX2: =IFERROR(VLOOKUP($A2,'[1]Donor-Served OBs'!A:N,16,0),0) -> 0 | AY2: =ROUNDUP(IF(A2=0,0,IFERROR(VLOOKUP($A2,'[1]Donor''s Assigned Kilos'!A:O,16,0),0)),0) -> 0 | AZ2: =IF(A2=0,0,IFERROR(SUMIFS([1]Population!Y:Y,[1]Population!J:J,'MASTER-2025'!A2),0)) -> 0 | BA2: =+H2+K2+N2+Q2+T2+W2+Z2+AC2+AF2+AI2+AL2+AO2+AR2+AU2+AX2 -> 0 | BB2: =INT(I2+L2+O2+R2+U2+X2+AA2+AD2+AG2+AJ2+AM2+AP2+AS2+AV2+AY2) -> 0 | BC2: =ROUND(I2+L2+O2+R2+U2,0) -> 0 | BD2: =IF(A2=0,0,(+J2+M2+P2+S2+V2+Y2+AB2+AE2+AH2+AK2+AN2+AQ2+AT2+AW2+AZ2)) -> 0 | BE2: =IF(A2=0,0,SUMIFS([1]Population!C:C,[1]Population!A:A,'MASTER-2025'!A2)) -> #VALUE! | BF2: =IF(A2=0,0,SUMIFS([1]Population!D:D,[1]Population!A:A,'MASTER-2025'!A2)) -> #VALUE! | BG2: =IF(A2=0,0,SUMIFS([1]Population!E:E,[1]Population!A:A,'MASTER-2025'!A2)) -> #VALUE! | BH2: =IF(A2=0,0,SUMIFS([1]Population!F:F,[1]Population!A:A,'MASTER-2025'!A2)) -> #VALUE! | BI2: =+BF2+BG2+BH2 -> #VALUE! | BJ2: =+BK2-BI2-BH2-BG2-BF2-BE2 -> #VALUE! | BK2: =IF(A2=0,0,SUMIFS([1]Population!G:G,[1]Population!A:A,'MASTER-2025'!A2)) -> #VALUE! | BL2: {=IFERROR(VLOOKUP(A2,'[1]Now-OB-kg-POB-25'!A:AQ,{3,4,5,6,7,8,9,10,11,12,13,14},0),0)} -> 60 | BM2: 53 | BN2: 88 | BO2: 0 | BP2: 0 | BQ2: 0 | BR2: 0 | BS2: 0 | BT2: 0 | BU2: 0 | BV2: 0 | BW2: 0 | BX2: =SUM(BL2:BW2) -> 201 | BY2: {=IFERROR(VLOOKUP(A2,'[1]Now-OB-kg-POB-25'!A:AQ,{17,18,19,20,21,22,23,24,25,26,27,28},0),0)} -> 6112 | BZ2: 752 | CA2: 2508 | CB2: 0 | CC2: 0 | CD2: 0 | CE2: 0 | CF2: 0 | CG2: 0 | CH2: 0 | CI2: 0 | CJ2: 0 | CK2: =SUM(BY2:CJ2) -> 9372 | CL2: {=IFERROR(VLOOKUP(A2,'[1]Now-OB-kg-POB-25'!A:AQ,{31,32,33,34,35,36,37,38,39,40,41,42},0),0)} -> 19341 | CM2: 16959 | CN2: 26002 | CO2: 0 | CP2: 0 | CQ2: 0 | CR2: 0 | CS2: 0 | CT2: 0 | CU2: 0 | CV2: 0 | CW2: 0 | CX2: =SUM(CL2:CW2) -> 62302 | CY2: =IF(A2=0,0,IFERROR(VLOOKUP(A2,'[1]Info Donantes'!C:F,2,0),"Sin Contacto")) -> Sin Contacto | CZ2: =IF(A2=0,0,IFERROR(VLOOKUP(A2,'[1]Info Donantes'!C:F,3,0),"Sin Correo")) -> Sin Correo | DA2: =IF(A2=0,0,IFERROR(VLOOKUP(A2,'[1]Info Donantes'!C:F,4,0),"Sin Telefono")) -> Sin Telefono | DB2: Traceability Report - - FEDURO AGENCIES
A3: ALIMENTOS CÁRNICOS DE PANAMA, S.A | B3: =INT(IFERROR(VLOOKUP(A3,'[1]Donor Summary'!C:F,3,0),0)) -> 0 | C3: =INT(ROUND(IFERROR(VLOOKUP(A3,'[1]Donor Summary'!C:F,4,0),0),1)) -> 0 | D3: =INT(ROUND(C3-B3,1)) -> 0 | E3: =IF(A3=0,"",TEXT((IFERROR(D3/C3,0)),"0.00%")) -> 0.00% | F3: =IF(A3=0,"",TEXT((IFERROR(B3/C3,0)),"0.0%")) -> 0.0% | G3: =INT(D3*3) -> 0 | I3: =IFERROR(VLOOKUP(A3,'[1]Lot All by Part'!T:Y,6,0),0) -> 0 | K3: =IFERROR(VLOOKUP($A3,'[1]Donor-Served OBs'!A:N,3,0),0) -> 0 | L3: =ROUNDUP(IF(A3=0,0,IFERROR(VLOOKUP($A3,'[1]Donor''s Assigned Kilos'!A:O,3,0),0)),0) -> 0 | M3: =IF(A3=0,0,IFERROR(SUMIFS([1]Population!M:M,[1]Population!J:J,'MASTER-2025'!A3),0)) -> 0 | N3: =IFERROR(VLOOKUP($A3,'[1]Donor-Served OBs'!A:N,4,0),0) -> 0 | O3: =ROUNDUP(IF(A3=0,0,IFERROR(VLOOKUP($A3,'[1]Donor''s Assigned Kilos'!A:O,4,0),0)),0) -> 0 | P3: =IF(A3=0,0,IFERROR(SUMIFS([1]Population!N:N,[1]Population!J:J,'MASTER-2025'!A3),0)) -> 0 | Q3: =IFERROR(VLOOKUP($A3,'[1]Donor-Served OBs'!A:N,2,0),0) -> 0 | R3: =ROUNDUP(ROUND(IF(A3=0,0,IFERROR(VLOOKUP($A3,'[1]Donor''s Assigned Kilos'!A:O,9,0),0)),1),0) -> 0 | S3: =IF(A3=0,0,IFERROR(SUMIFS([1]Population!S:S,[1]Population!J:J,'MASTER-2025'!A3),0)) -> 0 | T3: =IFERROR(VLOOKUP($A3,'[1]Donor-Served OBs'!A:N,12,0),0) -> 0 | U3: =ROUNDUP(IF(A3=0,0,IF(A3=0,0,IFERROR(VLOOKUP($A3,'[1]Donor''s Assigned Kilos'!A:O,7,0),0))),0) -> 0 | V3: =IF(A3=0,0,IFERROR(SUMIFS([1]Population!Q:Q,[1]Population!J:J,'MASTER-2025'!A3),0)) -> 0 | W3: =IFERROR(VLOOKUP($A3,'[1]Donor-Served OBs'!A:N,10,0),0) -> 0 | X3: =ROUNDUP(IF(A3=0,0,IFERROR(VLOOKUP($A3,'[1]Donor''s Assigned Kilos'!A:N,5,0),0)),0) -> 0 | Y3: =IF(A3=0,0,IFERROR(SUMIFS([1]Population!O:O,[1]Population!J:J,'MASTER-2025'!A3),0)) -> 0 | Z3: =IFERROR(VLOOKUP($A3,'[1]Donor-Served OBs'!A:N,6,0),0) -> 0 | AA3: =ROUNDUP(IF(A3=0,0,IFERROR(VLOOKUP($A3,'[1]Donor''s Assigned Kilos'!A:N,11,0),0)),0) -> 0 | AB3: =IF(A3=0,0,IFERROR(SUMIFS([1]Population!U:U,[1]Population!J:J,'MASTER-2025'!A3),0)) -> 0 | AC3: =IFERROR(VLOOKUP($A3,'[1]Donor-Served OBs'!A:N,7,0),0) -> 0 | AD3: =ROUNDUP(IF(A3=0,0,IFERROR(VLOOKUP($A3,'[1]Donor''s Assigned Kilos'!A:N,8,0),0)),0) -> 0 | AE3: =IF(A3=0,0,IFERROR(SUMIFS([1]Population!R:R,[1]Population!J:J,'MASTER-2025'!A3),0)) -> 0 | AF3: =IFERROR(VLOOKUP($A3,'[1]Donor-Served OBs'!A:N,8,0),0) -> 0 | AG3: =ROUNDUP(IF(A3=0,0,IFERROR(VLOOKUP($A3,'[1]Donor''s Assigned Kilos'!A:N,6,0),0)),0) -> 0 | AH3: =IF(A3=0,0,IFERROR(SUMIFS([1]Population!P:P,[1]Population!J:J,'MASTER-2025'!A3),0)) -> 0 | AI3: =IFERROR(VLOOKUP($A3,'[1]Donor-Served OBs'!A:N,9,0),0) -> 0 | AJ3: =ROUNDUP(IF(A3=0,0,IFERROR(VLOOKUP($A3,'[1]Donor''s Assigned Kilos'!A:N,12,0),0)),0) -> 0 | AK3: =IF(A3=0,0,IFERROR(SUMIFS([1]Population!V:V,[1]Population!J:J,'MASTER-2025'!A3),0)) -> 0 | AL3: =IFERROR(VLOOKUP($A3,'[1]Donor-Served OBs'!A:N,16,0),0) -> 0 | AM3: =ROUNDUP(IF(A3=0,0,IFERROR(VLOOKUP($A3,'[1]Donor''s Assigned Kilos'!A:O,16,0),0)),0) -> 0 | AN3: =IF(A3=0,0,IFERROR(SUMIFS([1]Population!Z:Z,[1]Population!J:J,'MASTER-2025'!A3),0)) -> 0 | AO3: =IFERROR(VLOOKUP($A3,'[1]Donor-Served OBs'!A:N,11,0),0) -> 0 | AP3: =ROUNDUP(IF(A3=0,0,IFERROR(VLOOKUP($A3,'[1]Donor''s Assigned Kilos'!A:N,13,0),0)),0) -> 0 | AQ3: =IF(A3=0,0,IFERROR(SUMIFS([1]Population!W:W,[1]Population!J:J,'MASTER-2025'!A3),0)) -> 0 | AR3: =IFERROR(VLOOKUP($A3,'[1]Donor-Served OBs'!A:N,5,0),0) -> 0 | AS3: =ROUNDUP(IF(A3=0,0,IFERROR(VLOOKUP($A3,'[1]Donor''s Assigned Kilos'!A:N,10,0),0)),0) -> 0 | AT3: =IF(A3=0,0,IFERROR(SUMIFS([1]Population!T:T,[1]Population!J:J,'MASTER-2025'!A3),0)) -> 0 | AU3: =IFERROR(VLOOKUP($A3,'[1]Donor-Served OBs'!A:N,13,0),0) -> 0 | AV3: =ROUNDUP(IF(A3=0,0,IFERROR(VLOOKUP($A3,'[1]Donor''s Assigned Kilos'!A:N,14,0),0)),0) -> 0 | AW3: =IF(A3=0,0,IFERROR(SUMIFS([1]Population!X:X,[1]Population!J:J,'MASTER-2025'!A3),0)) -> 0 | AX3: =IFERROR(VLOOKUP($A3,'[1]Donor-Served OBs'!A:N,16,0),0) -> 0 | AY3: =ROUNDUP(IF(A3=0,0,IFERROR(VLOOKUP($A3,'[1]Donor''s Assigned Kilos'!A:O,16,0),0)),0) -> 0 | AZ3: =IF(A3=0,0,IFERROR(SUMIFS([1]Population!Y:Y,[1]Population!J:J,'MASTER-2025'!A3),0)) -> 0 | BA3: =+H3+K3+N3+Q3+T3+W3+Z3+AC3+AF3+AI3+AL3+AO3+AR3+AU3+AX3 -> 0 | BB3: =INT(I3+L3+O3+R3+U3+X3+AA3+AD3+AG3+AJ3+AM3+AP3+AS3+AV3+AY3) -> 0 | BC3: =ROUND(I3+L3+O3+R3+U3,0) -> 0 | BD3: =IF(A3=0,0,(+J3+M3+P3+S3+V3+Y3+AB3+AE3+AH3+AK3+AN3+AQ3+AT3+AW3+AZ3)) -> 0 | BE3: =IF(A3=0,0,SUMIFS([1]Population!C:C,[1]Population!A:A,'MASTER-2025'!A3)) -> #VALUE! | BF3: =IF(A3=0,0,SUMIFS([1]Population!D:D,[1]Population!A:A,'MASTER-2025'!A3)) -> #VALUE! | BG3: =IF(A3=0,0,SUMIFS([1]Population!E:E,[1]Population!A:A,'MASTER-2025'!A3)) -> #VALUE! | BH3: =IF(A3=0,0,SUMIFS([1]Population!F:F,[1]Population!A:A,'MASTER-2025'!A3)) -> #VALUE! | BI3: =+BF3+BG3+BH3 -> #VALUE! | BJ3: =+BK3-BI3-BH3-BG3-BF3-BE3 -> #VALUE! | BK3: =IF(A3=0,0,SUMIFS([1]Population!G:G,[1]Population!A:A,'MASTER-2025'!A3)) -> #VALUE! | BL3: {=IFERROR(VLOOKUP(A3,'[1]Now-OB-kg-POB-25'!A:AQ,{3,4,5,6,7,8,9,10,11,12,13,14},0),0)} -> 34 | BM3: 0 | BN3: 13 | BO3: 0 | BP3: 0 | BQ3: 0 | BR3: 0 | BS3: 0 | BT3: 0 | BU3: 0 | BV3: 0 | BW3: 0 | BX3: =SUM(BL3:BW3) -> 47 | BY3: {=IFERROR(VLOOKUP(A3,'[1]Now-OB-kg-POB-25'!A:AQ,{17,18,19,20,21,22,23,24,25,26,27,28},0),0)} -> 1045 | BZ3: 0 | CA3: 108 | CB3: 0 | CC3: 0 | CD3: 0 | CE3: 0 | CF3: 0 | CG3: 0 | CH3: 0 | CI3: 0 | CJ3: 0 | CK3: =SUM(BY3:CJ3) -> 1153 | CL3: {=IFERROR(VLOOKUP(A3,'[1]Now-OB-kg-POB-25'!A:AQ,{31,32,33,34,35,36,37,38,39,40,41,42},0),0)} -> 11762 | CM3: 0 | CN3: 3455 | CO3: 0 | CP3: 0 | CQ3: 0 | CR3: 0 | CS3: 0 | CT3: 0 | CU3: 0 | CV3: 0 | CW3: 0 | CX3: =SUM(CL3:CW3) -> 15217 | CY3: =IF(A3=0,0,IFERROR(VLOOKUP(A3,'[1]Info Donantes'!C:F,2,0),"Sin Contacto")) -> Sin Contacto | CZ3: =IF(A3=0,0,IFERROR(VLOOKUP(A3,'[1]Info Donantes'!C:F,3,0),"Sin Correo")) -> Sin Correo | DA3: =IF(A3=0,0,IFERROR(VLOOKUP(A3,'[1]Info Donantes'!C:F,4,0),"Sin Telefono")) -> Sin Telefono | DB3: Traceability Report - - ALIMENTOS CÁRNICOS DE PANAMA, S.A
A4: ALIMENTOS NICO, S.A, (ANICSA) | B4: =INT(IFERROR(VLOOKUP(A4,'[1]Donor Summary'!C:F,3,0),0)) -> 0 | C4: =INT(ROUND(IFERROR(VLOOKUP(A4,'[1]Donor Summary'!C:F,4,0),0),1)) -> 0 | D4: =INT(ROUND(C4-B4,1)) -> 0 | E4: =IF(A4=0,"",TEXT((IFERROR(D4/C4,0)),"0.00%")) -> 0.00% | F4: =IF(A4=0,"",TEXT((IFERROR(B4/C4,0)),"0.0%")) -> 0.0% | G4: =INT(D4*3) -> 0 | I4: =IFERROR(VLOOKUP(A4,'[1]Lot All by Part'!T:Y,6,0),0) -> 0 | K4: =IFERROR(VLOOKUP($A4,'[1]Donor-Served OBs'!A:N,3,0),0) -> 0 | L4: =ROUNDUP(IF(A4=0,0,IFERROR(VLOOKUP($A4,'[1]Donor''s Assigned Kilos'!A:O,3,0),0)),0) -> 0 | M4: =IF(A4=0,0,IFERROR(SUMIFS([1]Population!M:M,[1]Population!J:J,'MASTER-2025'!A4),0)) -> 0 | N4: =IFERROR(VLOOKUP($A4,'[1]Donor-Served OBs'!A:N,4,0),0) -> 0 | O4: =ROUNDUP(IF(A4=0,0,IFERROR(VLOOKUP($A4,'[1]Donor''s Assigned Kilos'!A:O,4,0),0)),0) -> 0 | P4: =IF(A4=0,0,IFERROR(SUMIFS([1]Population!N:N,[1]Population!J:J,'MASTER-2025'!A4),0)) -> 0 | Q4: =IFERROR(VLOOKUP($A4,'[1]Donor-Served OBs'!A:N,2,0),0) -> 0 | R4: =ROUNDUP(ROUND(IF(A4=0,0,IFERROR(VLOOKUP($A4,'[1]Donor''s Assigned Kilos'!A:O,9,0),0)),1),0) -> 0 | S4: =IF(A4=0,0,IFERROR(SUMIFS([1]Population!S:S,[1]Population!J:J,'MASTER-2025'!A4),0)) -> 0 | T4: =IFERROR(VLOOKUP($A4,'[1]Donor-Served OBs'!A:N,12,0),0) -> 0 | U4: =ROUNDUP(IF(A4=0,0,IF(A4=0,0,IFERROR(VLOOKUP($A4,'[1]Donor''s Assigned Kilos'!A:O,7,0),0))),0) -> 0 | V4: =IF(A4=0,0,IFERROR(SUMIFS([1]Population!Q:Q,[1]Population!J:J,'MASTER-2025'!A4),0)) -> 0 | W4: =IFERROR(VLOOKUP($A4,'[1]Donor-Served OBs'!A:N,10,0),0) -> 0 | X4: =ROUNDUP(IF(A4=0,0,IFERROR(VLOOKUP($A4,'[1]Donor''s Assigned Kilos'!A:N,5,0),0)),0) -> 0 | Y4: =IF(A4=0,0,IFERROR(SUMIFS([1]Population!O:O,[1]Population!J:J,'MASTER-2025'!A4),0)) -> 0 | Z4: =IFERROR(VLOOKUP($A4,'[1]Donor-Served OBs'!A:N,6,0),0) -> 0 | AA4: =ROUNDUP(IF(A4=0,0,IFERROR(VLOOKUP($A4,'[1]Donor''s Assigned Kilos'!A:N,11,0),0)),0) -> 0 | AB4: =IF(A4=0,0,IFERROR(SUMIFS([1]Population!U:U,[1]Population!J:J,'MASTER-2025'!A4),0)) -> 0 | AC4: =IFERROR(VLOOKUP($A4,'[1]Donor-Served OBs'!A:N,7,0),0) -> 0 | AD4: =ROUNDUP(IF(A4=0,0,IFERROR(VLOOKUP($A4,'[1]Donor''s Assigned Kilos'!A:N,8,0),0)),0) -> 0 | AE4: =IF(A4=0,0,IFERROR(SUMIFS([1]Population!R:R,[1]Population!J:J,'MASTER-2025'!A4),0)) -> 0 | AF4: =IFERROR(VLOOKUP($A4,'[1]Donor-Served OBs'!A:N,8,0),0) -> 0 | AG4: =ROUNDUP(IF(A4=0,0,IFERROR(VLOOKUP($A4,'[1]Donor''s Assigned Kilos'!A:N,6,0),0)),0) -> 0 | AH4: =IF(A4=0,0,IFERROR(SUMIFS([1]Population!P:P,[1]Population!J:J,'MASTER-2025'!A4),0)) -> 0 | AI4: =IFERROR(VLOOKUP($A4,'[1]Donor-Served OBs'!A:N,9,0),0) -> 0 | AJ4: =ROUNDUP(IF(A4=0,0,IFERROR(VLOOKUP($A4,'[1]Donor''s Assigned Kilos'!A:N,12,0),0)),0) -> 0 | AK4: =IF(A4=0,0,IFERROR(SUMIFS([1]Population!V:V,[1]Population!J:J,'MASTER-2025'!A4),0)) -> 0 | AL4: =IFERROR(VLOOKUP($A4,'[1]Donor-Served OBs'!A:N,16,0),0) -> 0 | AM4: =ROUNDUP(IF(A4=0,0,IFERROR(VLOOKUP($A4,'[1]Donor''s Assigned Kilos'!A:O,16,0),0)),0) -> 0 | AN4: =IF(A4=0,0,IFERROR(SUMIFS([1]Population!Z:Z,[1]Population!J:J,'MASTER-2025'!A4),0)) -> 0 | AO4: =IFERROR(VLOOKUP($A4,'[1]Donor-Served OBs'!A:N,11,0),0) -> 0 | AP4: =ROUNDUP(IF(A4=0,0,IFERROR(VLOOKUP($A4,'[1]Donor''s Assigned Kilos'!A:N,13,0),0)),0) -> 0 | AQ4: =IF(A4=0,0,IFERROR(SUMIFS([1]Population!W:W,[1]Population!J:J,'MASTER-2025'!A4),0)) -> 0 | AR4: =IFERROR(VLOOKUP($A4,'[1]Donor-Served OBs'!A:N,5,0),0) -> 0 | AS4: =ROUNDUP(IF(A4=0,0,IFERROR(VLOOKUP($A4,'[1]Donor''s Assigned Kilos'!A:N,10,0),0)),0) -> 0 | AT4: =IF(A4=0,0,IFERROR(SUMIFS([1]Population!T:T,[1]Population!J:J,'MASTER-2025'!A4),0)) -> 0 | AU4: =IFERROR(VLOOKUP($A4,'[1]Donor-Served OBs'!A:N,13,0),0) -> 0 | AV4: =ROUNDUP(IF(A4=0,0,IFERROR(VLOOKUP($A4,'[1]Donor''s Assigned Kilos'!A:N,14,0),0)),0) -> 0 | AW4: =IF(A4=0,0,IFERROR(SUMIFS([1]Population!X:X,[1]Population!J:J,'MASTER-2025'!A4),0)) -> 0 | AX4: =IFERROR(VLOOKUP($A4,'[1]Donor-Served OBs'!A:N,16,0),0) -> 0 | AY4: =ROUNDUP(IF(A4=0,0,IFERROR(VLOOKUP($A4,'[1]Donor''s Assigned Kilos'!A:O,16,0),0)),0) -> 0 | AZ4: =IF(A4=0,0,IFERROR(SUMIFS([1]Population!Y:Y,[1]Population!J:J,'MASTER-2025'!A4),0)) -> 0 | BA4: =+H4+K4+N4+Q4+T4+W4+Z4+AC4+AF4+AI4+AL4+AO4+AR4+AU4+AX4 -> 0 | BB4: =INT(I4+L4+O4+R4+U4+X4+AA4+AD4+AG4+AJ4+AM4+AP4+AS4+AV4+AY4) -> 0 | BC4: =ROUND(I4+L4+O4+R4+U4,0) -> 0 | BD4: =IF(A4=0,0,(+J4+M4+P4+S4+V4+Y4+AB4+AE4+AH4+AK4+AN4+AQ4+AT4+AW4+AZ4)) -> 0 | BE4: =IF(A4=0,0,SUMIFS([1]Population!C:C,[1]Population!A:A,'MASTER-2025'!A4)) -> #VALUE! | BF4: =IF(A4=0,0,SUMIFS([1]Population!D:D,[1]Population!A:A,'MASTER-2025'!A4)) -> #VALUE! | BG4: =IF(A4=0,0,SUMIFS([1]Population!E:E,[1]Population!A:A,'MASTER-2025'!A4)) -> #VALUE! | BH4: =IF(A4=0,0,SUMIFS([1]Population!F:F,[1]Population!A:A,'MASTER-2025'!A4)) -> #VALUE! | BI4: =+BF4+BG4+BH4 -> #VALUE! | BJ4: =+BK4-BI4-BH4-BG4-BF4-BE4 -> #VALUE! | BK4: =IF(A4=0,0,SUMIFS([1]Population!G:G,[1]Population!A:A,'MASTER-2025'!A4)) -> #VALUE! | BL4: {=IFERROR(VLOOKUP(A4,'[1]Now-OB-kg-POB-25'!A:AQ,{3,4,5,6,7,8,9,10,11,12,13,14},0),0)} -> 0 | BM4: 0 | BN4: 0 | BO4: 0 | BP4: 0 | BQ4: 0 | BR4: 0 | BS4: 0 | BT4: 0 | BU4: 0 | BV4: 0 | BW4: 0 | BX4: =SUM(BL4:BW4) -> 0 | BY4: {=IFERROR(VLOOKUP(A4,'[1]Now-OB-kg-POB-25'!A:AQ,{17,18,19,20,21,22,23,24,25,26,27,28},0),0)} -> 0 | BZ4: 0 | CA4: 0 | CB4: 0 | CC4: 0 | CD4: 0 | CE4: 0 | CF4: 0 | CG4: 0 | CH4: 0 | CI4: 0 | CJ4: 0 | CK4: =SUM(BY4:CJ4) -> 0 | CL4: {=IFERROR(VLOOKUP(A4,'[1]Now-OB-kg-POB-25'!A:AQ,{31,32,33,34,35,36,37,38,39,40,41,42},0),0)} -> 0 | CM4: 0 | CN4: 0 | CO4: 0 | CP4: 0 | CQ4: 0 | CR4: 0 | CS4: 0 | CT4: 0 | CU4: 0 | CV4: 0 | CW4: 0 | CX4: =SUM(CL4:CW4) -> 0 | CY4: =IF(A4=0,0,IFERROR(VLOOKUP(A4,'[1]Info Donantes'!C:F,2,0),"Sin Contacto")) -> David Yanguez | CZ4: =IF(A4=0,0,IFERROR(VLOOKUP(A4,'[1]Info Donantes'!C:F,3,0),"Sin Correo")) -> cafe.don.tino@hotmail.com | DA4: =IF(A4=0,0,IFERROR(VLOOKUP(A4,'[1]Info Donantes'!C:F,4,0),"Sin Telefono")) -> 851 0138 | DB4: Traceability Report - - ALIMENTOS NICO, S.A, (ANICSA)
A5: Bienes y Raices Metalicas S.A. | B5: =INT(IFERROR(VLOOKUP(A5,'[1]Donor Summary'!C:F,3,0),0)) -> 0 | C5: =INT(ROUND(IFERROR(VLOOKUP(A5,'[1]Donor Summary'!C:F,4,0),0),1)) -> 45 | D5: =INT(ROUND(C5-B5,1)) -> 45 | E5: =IF(A5=0,"",TEXT((IFERROR(D5/C5,0)),"0.00%")) -> 100.00% | F5: =IF(A5=0,"",TEXT((IFERROR(B5/C5,0)),"0.0%")) -> 0.0% | G5: =INT(D5*3) -> 135 | I5: =IFERROR(VLOOKUP(A5,'[1]Lot All by Part'!T:Y,6,0),0) -> 0 | K5: =IFERROR(VLOOKUP($A5,'[1]Donor-Served OBs'!A:N,3,0),0) -> 0 | L5: =ROUNDUP(IF(A5=0,0,IFERROR(VLOOKUP($A5,'[1]Donor''s Assigned Kilos'!A:O,3,0),0)),0) -> 0 | M5: =IF(A5=0,0,IFERROR(SUMIFS([1]Population!M:M,[1]Population!J:J,'MASTER-2025'!A5),0)) -> 0 | N5: =IFERROR(VLOOKUP($A5,'[1]Donor-Served OBs'!A:N,4,0),0) -> 0 | O5: =ROUNDUP(IF(A5=0,0,IFERROR(VLOOKUP($A5,'[1]Donor''s Assigned Kilos'!A:O,4,0),0)),0) -> 0 | P5: =IF(A5=0,0,IFERROR(SUMIFS([1]Population!N:N,[1]Population!J:J,'MASTER-2025'!A5),0)) -> 0 | Q5: =IFERROR(VLOOKUP($A5,'[1]Donor-Served OBs'!A:N,2,0),0) -> 0 | R5: =ROUNDUP(ROUND(IF(A5=0,0,IFERROR(VLOOKUP($A5,'[1]Donor''s Assigned Kilos'!A:O,9,0),0)),1),0) -> 0 | S5: =IF(A5=0,0,IFERROR(SUMIFS([1]Population!S:S,[1]Population!J:J,'MASTER-2025'!A5),0)) -> 0 | T5: =IFERROR(VLOOKUP($A5,'[1]Donor-Served OBs'!A:N,12,0),0) -> 0 | U5: =ROUNDUP(IF(A5=0,0,IF(A5=0,0,IFERROR(VLOOKUP($A5,'[1]Donor''s Assigned Kilos'!A:O,7,0),0))),0) -> 0 | V5: =IF(A5=0,0,IFERROR(SUMIFS([1]Population!Q:Q,[1]Population!J:J,'MASTER-2025'!A5),0)) -> 0 | W5: =IFERROR(VLOOKUP($A5,'[1]Donor-Served OBs'!A:N,10,0),0) -> 0 | X5: =ROUNDUP(IF(A5=0,0,IFERROR(VLOOKUP($A5,'[1]Donor''s Assigned Kilos'!A:N,5,0),0)),0) -> 0 | Y5: =IF(A5=0,0,IFERROR(SUMIFS([1]Population!O:O,[1]Population!J:J,'MASTER-2025'!A5),0)) -> 0 | Z5: =IFERROR(VLOOKUP($A5,'[1]Donor-Served OBs'!A:N,6,0),0) -> 1 | AA5: =ROUNDUP(IF(A5=0,0,IFERROR(VLOOKUP($A5,'[1]Donor''s Assigned Kilos'!A:N,11,0),0)),0) -> 3 | AB5: =IF(A5=0,0,IFERROR(SUMIFS([1]Population!U:U,[1]Population!J:J,'MASTER-2025'!A5),0)) -> 0 | AC5: =IFERROR(VLOOKUP($A5,'[1]Donor-Served OBs'!A:N,7,0),0) -> 0 | AD5: =ROUNDUP(IF(A5=0,0,IFERROR(VLOOKUP($A5,'[1]Donor''s Assigned Kilos'!A:N,8,0),0)),0) -> 0 | AE5: =IF(A5=0,0,IFERROR(SUMIFS([1]Population!R:R,[1]Population!J:J,'MASTER-2025'!A5),0)) -> 0 | AF5: =IFERROR(VLOOKUP($A5,'[1]Donor-Served OBs'!A:N,8,0),0) -> 0 | AG5: =ROUNDUP(IF(A5=0,0,IFERROR(VLOOKUP($A5,'[1]Donor''s Assigned Kilos'!A:N,6,0),0)),0) -> 0 | AH5: =IF(A5=0,0,IFERROR(SUMIFS([1]Population!P:P,[1]Population!J:J,'MASTER-2025'!A5),0)) -> 0 | AI5: =IFERROR(VLOOKUP($A5,'[1]Donor-Served OBs'!A:N,9,0),0) -> 1 | AJ5: =ROUNDUP(IF(A5=0,0,IFERROR(VLOOKUP($A5,'[1]Donor''s Assigned Kilos'!A:N,12,0),0)),0) -> 3 | AK5: =IF(A5=0,0,IFERROR(SUMIFS([1]Population!V:V,[1]Population!J:J,'MASTER-2025'!A5),0)) -> 0 | AL5: =IFERROR(VLOOKUP($A5,'[1]Donor-Served OBs'!A:N,16,0),0) -> 0 | AM5: =ROUNDUP(IF(A5=0,0,IFERROR(VLOOKUP($A5,'[1]Donor''s Assigned Kilos'!A:O,16,0),0)),0) -> 0 | AN5: =IF(A5=0,0,IFERROR(SUMIFS([1]Population!Z:Z,[1]Population!J:J,'MASTER-2025'!A5),0)) -> 0 | AO5: =IFERROR(VLOOKUP($A5,'[1]Donor-Served OBs'!A:N,11,0),0) -> 0 | AP5: =ROUNDUP(IF(A5=0,0,IFERROR(VLOOKUP($A5,'[1]Donor''s Assigned Kilos'!A:N,13,0),0)),0) -> 0 | AQ5: =IF(A5=0,0,IFERROR(SUMIFS([1]Population!W:W,[1]Population!J:J,'MASTER-2025'!A5),0)) -> 0 | AR5: =IFERROR(VLOOKUP($A5,'[1]Donor-Served OBs'!A:N,5,0),0) -> 0 | AS5: =ROUNDUP(IF(A5=0,0,IFERROR(VLOOKUP($A5,'[1]Donor''s Assigned Kilos'!A:N,10,0),0)),0) -> 0 | AT5: =IF(A5=0,0,IFERROR(SUMIFS([1]Population!T:T,[1]Population!J:J,'MASTER-2025'!A5),0)) -> 0 | AU5: =IFERROR(VLOOKUP($A5,'[1]Donor-Served OBs'!A:N,13,0),0) -> 0 | AV5: =ROUNDUP(IF(A5=0,0,IFERROR(VLOOKUP($A5,'[1]Donor''s Assigned Kilos'!A:N,14,0),0)),0) -> 0 | AW5: =IF(A5=0,0,IFERROR(SUMIFS([1]Population!X:X,[1]Population!J:J,'MASTER-2025'!A5),0)) -> 0 | AX5: =IFERROR(VLOOKUP($A5,'[1]Donor-Served OBs'!A:N,16,0),0) -> 0 | AY5: =ROUNDUP(IF(A5=0,0,IFERROR(VLOOKUP($A5,'[1]Donor''s Assigned Kilos'!A:O,16,0),0)),0) -> 0 | AZ5: =IF(A5=0,0,IFERROR(SUMIFS([1]Population!Y:Y,[1]Population!J:J,'MASTER-2025'!A5),0)) -> 0 | BA5: =+H5+K5+N5+Q5+T5+W5+Z5+AC5+AF5+AI5+AL5+AO5+AR5+AU5+AX5 -> 2 | BB5: =INT(I5+L5+O5+R5+U5+X5+AA5+AD5+AG5+AJ5+AM5+AP5+AS5+AV5+AY5) -> 6 | BC5: =ROUND(I5+L5+O5+R5+U5,0) -> 0 | BD5: =IF(A5=0,0,(+J5+M5+P5+S5+V5+Y5+AB5+AE5+AH5+AK5+AN5+AQ5+AT5+AW5+AZ5)) -> 0 | BE5: =IF(A5=0,0,SUMIFS([1]Population!C:C,[1]Population!A:A,'MASTER-2025'!A5)) -> #VALUE! | BF5: =IF(A5=0,0,SUMIFS([1]Population!D:D,[1]Population!A:A,'MASTER-2025'!A5)) -> #VALUE! | BG5: =IF(A5=0,0,SUMIFS([1]Population!E:E,[1]Population!A:A,'MASTER-2025'!A5)) -> #VALUE! | BH5: =IF(A5=0,0,SUMIFS([1]Population!F:F,[1]Population!A:A,'MASTER-2025'!A5)) -> #VALUE! | BI5: =+BF5+BG5+BH5 -> #VALUE! | BJ5: =+BK5-BI5-BH5-BG5-BF5-BE5 -> #VALUE! | BK5: =IF(A5=0,0,SUMIFS([1]Population!G:G,[1]Population!A:A,'MASTER-2025'!A5)) -> #VALUE! | BL5: {=IFERROR(VLOOKUP(A5,'[1]Now-OB-kg-POB-25'!A:AQ,{3,4,5,6,7,8,9,10,11,12,13,14},0),0)} -> 0 | BM5: 3 | BN5: 2 | BO5: 0 | BP5: 0 | BQ5: 0 | BR5: 0 | BS5: 0 | BT5: 0 | BU5: 0 | BV5: 0 | BW5: 0 | BX5: =SUM(BL5:BW5) -> 5 | BY5: {=IFERROR(VLOOKUP(A5,'[1]Now-OB-kg-POB-25'!A:AQ,{17,18,19,20,21,22,23,24,25,26,27,28},0),0)} -> 45 | BZ5: 45 | CA5: 45 | CB5: 0 | CC5: 0 | CD5: 0 | CE5: 0 | CF5: 0 | CG5: 0 | CH5: 0 | CI5: 0 | CJ5: 0 | CK5: =SUM(BY5:CJ5) -> 135 | CL5: {=IFERROR(VLOOKUP(A5,'[1]Now-OB-kg-POB-25'!A:AQ,{31,32,33,34,35,36,37,38,39,40,41,42},0),0)} -> 0 | CM5: 333 | CN5: 340 | CO5: 0 | CP5: 0 | CQ5: 0 | CR5: 0 | CS5: 0 | CT5: 0 | CU5: 0 | CV5: 0 | CW5: 0 | CX5: =SUM(CL5:CW5) -> 673 | CY5: =IF(A5=0,0,IFERROR(VLOOKUP(A5,'[1]Info Donantes'!C:F,2,0),"Sin Contacto")) -> Jose Tello | CZ5: =IF(A5=0,0,IFERROR(VLOOKUP(A5,'[1]Info Donantes'!C:F,3,0),"Sin Correo")) -> tmj1929@hotmail.com | DA5: =IF(A5=0,0,IFERROR(VLOOKUP(A5,'[1]Info Donantes'!C:F,4,0),"Sin Telefono")) -> 6675-0897 | DB5: Traceability Report - - Bienes y Raices Metalicas S.A.
A6: NATIONAL BREWERY | B6: =INT(IFERROR(VLOOKUP(A6,'[1]Donor Summary'!C:F,3,0),0)) -> 0 | C6: =INT(ROUND(IFERROR(VLOOKUP(A6,'[1]Donor Summary'!C:F,4,0),0),1)) -> 0 | D6: =INT(ROUND(C6-B6,1)) -> 0 | E6: =IF(A6=0,"",TEXT((IFERROR(D6/C6,0)),"0.00%")) -> 0.00% | F6: =IF(A6=0,"",TEXT((IFERROR(B6/C6,0)),"0.0%")) -> 0.0% | G6: =INT(D6*3) -> 0 | I6: =IFERROR(VLOOKUP(A6,'[1]Lot All by Part'!T:Y,6,0),0) -> 0 | K6: =IFERROR(VLOOKUP($A6,'[1]Donor-Served OBs'!A:N,3,0),0) -> 0 | L6: =ROUNDUP(IF(A6=0,0,IFERROR(VLOOKUP($A6,'[1]Donor''s Assigned Kilos'!A:O,3,0),0)),0) -> 0 | M6: =IF(A6=0,0,IFERROR(SUMIFS([1]Population!M:M,[1]Population!J:J,'MASTER-2025'!A6),0)) -> 0 | N6: =IFERROR(VLOOKUP($A6,'[1]Donor-Served OBs'!A:N,4,0),0) -> 0 | O6: =ROUNDUP(IF(A6=0,0,IFERROR(VLOOKUP($A6,'[1]Donor''s Assigned Kilos'!A:O,4,0),0)),0) -> 0 | P6: =IF(A6=0,0,IFERROR(SUMIFS([1]Population!N:N,[1]Population!J:J,'MASTER-2025'!A6),0)) -> 0 | Q6: =IFERROR(VLOOKUP($A6,'[1]Donor-Served OBs'!A:N,2,0),0) -> 0 | R6: =ROUNDUP(ROUND(IF(A6=0,0,IFERROR(VLOOKUP($A6,'[1]Donor''s Assigned Kilos'!A:O,9,0),0)),1),0) -> 0 | S6: =IF(A6=0,0,IFERROR(SUMIFS([1]Population!S:S,[1]Population!J:J,'MASTER-2025'!A6),0)) -> 0 | T6: =IFERROR(VLOOKUP($A6,'[1]Donor-Served OBs'!A:N,12,0),0) -> 0 | U6: =ROUNDUP(IF(A6=0,0,IF(A6=0,0,IFERROR(VLOOKUP($A6,'[1]Donor''s Assigned Kilos'!A:O,7,0),0))),0) -> 0 | V6: =IF(A6=0,0,IFERROR(SUMIFS([1]Population!Q:Q,[1]Population!J:J,'MASTER-2025'!A6),0)) -> 0 | W6: =IFERROR(VLOOKUP($A6,'[1]Donor-Served OBs'!A:N,10,0),0) -> 0 | X6: =ROUNDUP(IF(A6=0,0,IFERROR(VLOOKUP($A6,'[1]Donor''s Assigned Kilos'!A:N,5,0),0)),0) -> 0 | Y6: =IF(A6=0,0,IFERROR(SUMIFS([1]Population!O:O,[1]Population!J:J,'MASTER-2025'!A6),0)) -> 0 | Z6: =IFERROR(VLOOKUP($A6,'[1]Donor-Served OBs'!A:N,6,0),0) -> 0 | AA6: =ROUNDUP(IF(A6=0,0,IFERROR(VLOOKUP($A6,'[1]Donor''s Assigned Kilos'!A:N,11,0),0)),0) -> 0 | AB6: =IF(A6=0,0,IFERROR(SUMIFS([1]Population!U:U,[1]Population!J:J,'MASTER-2025'!A6),0)) -> 0 | AC6: =IFERROR(VLOOKUP($A6,'[1]Donor-Served OBs'!A:N,7,0),0) -> 0 | AD6: =ROUNDUP(IF(A6=0,0,IFERROR(VLOOKUP($A6,'[1]Donor''s Assigned Kilos'!A:N,8,0),0)),0) -> 0 | AE6: =IF(A6=0,0,IFERROR(SUMIFS([1]Population!R:R,[1]Population!J:J,'MASTER-2025'!A6),0)) -> 0 | AF6: =IFERROR(VLOOKUP($A6,'[1]Donor-Served OBs'!A:N,8,0),0) -> 0 | AG6: =ROUNDUP(IF(A6=0,0,IFERROR(VLOOKUP($A6,'[1]Donor''s Assigned Kilos'!A:N,6,0),0)),0) -> 0 | AH6: =IF(A6=0,0,IFERROR(SUMIFS([1]Population!P:P,[1]Population!J:J,'MASTER-2025'!A6),0)) -> 0 | AI6: =IFERROR(VLOOKUP($A6,'[1]Donor-Served OBs'!A:N,9,0),0) -> 0 | AJ6: =ROUNDUP(IF(A6=0,0,IFERROR(VLOOKUP($A6,'[1]Donor''s Assigned Kilos'!A:N,12,0),0)),0) -> 0 | AK6: =IF(A6=0,0,IFERROR(SUMIFS([1]Population!V:V,[1]Population!J:J,'MASTER-2025'!A6),0)) -> 0 | AL6: =IFERROR(VLOOKUP($A6,'[1]Donor-Served OBs'!A:N,16,0),0) -> 0 | AM6: =ROUNDUP(IF(A6=0,0,IFERROR(VLOOKUP($A6,'[1]Donor''s Assigned Kilos'!A:O,16,0),0)),0) -> 0 | AN6: =IF(A6=0,0,IFERROR(SUMIFS([1]Population!Z:Z,[1]Population!J:J,'MASTER-2025'!A6),0)) -> 0 | AO6: =IFERROR(VLOOKUP($A6,'[1]Donor-Served OBs'!A:N,11,0),0) -> 0 | AP6: =ROUNDUP(IF(A6=0,0,IFERROR(VLOOKUP($A6,'[1]Donor''s Assigned Kilos'!A:N,13,0),0)),0) -> 0 | AQ6: =IF(A6=0,0,IFERROR(SUMIFS([1]Population!W:W,[1]Population!J:J,'MASTER-2025'!A6),0)) -> 0 | AR6: =IFERROR(VLOOKUP($A6,'[1]Donor-Served OBs'!A:N,5,0),0) -> 0 | AS6: =ROUNDUP(IF(A6=0,0,IFERROR(VLOOKUP($A6,'[1]Donor''s Assigned Kilos'!A:N,10,0),0)),0) -> 0 | AT6: =IF(A6=0,0,IFERROR(SUMIFS([1]Population!T:T,[1]Population!J:J,'MASTER-2025'!A6),0)) -> 0 | AU6: =IFERROR(VLOOKUP($A6,'[1]Donor-Served OBs'!A:N,13,0),0) -> 0 | AV6: =ROUNDUP(IF(A6=0,0,IFERROR(VLOOKUP($A6,'[1]Donor''s Assigned Kilos'!A:N,14,0),0)),0) -> 0 | AW6: =IF(A6=0,0,IFERROR(SUMIFS([1]Population!X:X,[1]Population!J:J,'MASTER-2025'!A6),0)) -> 0 | AX6: =IFERROR(VLOOKUP($A6,'[1]Donor-Served OBs'!A:N,16,0),0) -> 0 | AY6: =ROUNDUP(IF(A6=0,0,IFERROR(VLOOKUP($A6,'[1]Donor''s Assigned Kilos'!A:O,16,0),0)),0) -> 0 | AZ6: =IF(A6=0,0,IFERROR(SUMIFS([1]Population!Y:Y,[1]Population!J:J,'MASTER-2025'!A6),0)) -> 0 | BA6: =+H6+K6+N6+Q6+T6+W6+Z6+AC6+AF6+AI6+AL6+AO6+AR6+AU6+AX6 -> 0 | BB6: =INT(I6+L6+O6+R6+U6+X6+AA6+AD6+AG6+AJ6+AM6+AP6+AS6+AV6+AY6) -> 0 | BC6: =ROUND(I6+L6+O6+R6+U6,0) -> 0 | BD6: =IF(A6=0,0,(+J6+M6+P6+S6+V6+Y6+AB6+AE6+AH6+AK6+AN6+AQ6+AT6+AW6+AZ6)) -> 0 | BE6: =IF(A6=0,0,SUMIFS([1]Population!C:C,[1]Population!A:A,'MASTER-2025'!A6)) -> #VALUE! | BF6: =IF(A6=0,0,SUMIFS([1]Population!D:D,[1]Population!A:A,'MASTER-2025'!A6)) -> #VALUE! | BG6: =IF(A6=0,0,SUMIFS([1]Population!E:E,[1]Population!A:A,'MASTER-2025'!A6)) -> #VALUE! | BH6: =IF(A6=0,0,SUMIFS([1]Population!F:F,[1]Population!A:A,'MASTER-2025'!A6)) -> #VALUE! | BI6: =+BF6+BG6+BH6 -> #VALUE! | BJ6: =+BK6-BI6-BH6-BG6-BF6-BE6 -> #VALUE! | BK6: =IF(A6=0,0,SUMIFS([1]Population!G:G,[1]Population!A:A,'MASTER-2025'!A6)) -> #VALUE! | BL6: {=IFERROR(VLOOKUP(A6,'[1]Now-OB-kg-POB-25'!A:AQ,{3,4,5,6,7,8,9,10,11,12,13,14},0),0)} -> 0 | BM6: 0 | BN6: 0 | BO6: 0 | BP6: 0 | BQ6: 0 | BR6: 0 | BS6: 0 | BT6: 0 | BU6: 0 | BV6: 0 | BW6: 0 | BX6: =SUM(BL6:BW6) -> 0 | BY6: {=IFERROR(VLOOKUP(A6,'[1]Now-OB-kg-POB-25'!A:AQ,{17,18,19,20,21,22,23,24,25,26,27,28},0),0)} -> 0 | BZ6: 0 | CA6: 0 | CB6: 0 | CC6: 0 | CD6: 0 | CE6: 0 | CF6: 0 | CG6: 0 | CH6: 0 | CI6: 0 | CJ6: 0 | CK6: =SUM(BY6:CJ6) -> 0 | CL6: {=IFERROR(VLOOKUP(A6,'[1]Now-OB-kg-POB-25'!A:AQ,{31,32,33,34,35,36,37,38,39,40,41,42},0),0)} -> 0 | CM6: 0 | CN6: 0 | CO6: 0 | CP6: 0 | CQ6: 0 | CR6: 0 | CS6: 0 | CT6: 0 | CU6: 0 | CV6: 0 | CW6: 0 | CX6: =SUM(CL6:CW6) -> 0 | CY6: =IF(A6=0,0,IFERROR(VLOOKUP(A6,'[1]Info Donantes'!C:F,2,0),"Sin Contacto")) -> Sin Contacto | CZ6: =IF(A6=0,0,IFERROR(VLOOKUP(A6,'[1]Info Donantes'!C:F,3,0),"Sin Correo")) -> Sin Correo | DA6: =IF(A6=0,0,IFERROR(VLOOKUP(A6,'[1]Info Donantes'!C:F,4,0),"Sin Telefono")) -> Sin Telefono | DB6: Traceability Report - - NATIONAL BREWERY
A7: KOL SHEARITH ISRAEL BROTHERHOOD CONGREGATION | B7: =INT(IFERROR(VLOOKUP(A7,'[1]Donor Summary'!C:F,3,0),0)) -> 0 | C7: =INT(ROUND(IFERROR(VLOOKUP(A7,'[1]Donor Summary'!C:F,4,0),0),1)) -> 0 | D7: =INT(ROUND(C7-B7,1)) -> 0 | E7: =IF(A7=0,"",TEXT((IFERROR(D7/C7,0)),"0.00%")) -> 0.00% | F7: =IF(A7=0,"",TEXT((IFERROR(B7/C7,0)),"0.0%")) -> 0.0% | G7: =INT(D7*3) -> 0 | I7: =IFERROR(VLOOKUP(A7,'[1]Lot All by Part'!T:Y,6,0),0) -> 0 | K7: =IFERROR(VLOOKUP($A7,'[1]Donor-Served OBs'!A:N,3,0),0) -> 0 | L7: =ROUNDUP(IF(A7=0,0,IFERROR(VLOOKUP($A7,'[1]Donor''s Assigned Kilos'!A:O,3,0),0)),0) -> 0 | M7: =IF(A7=0,0,IFERROR(SUMIFS([1]Population!M:M,[1]Population!J:J,'MASTER-2025'!A7),0)) -> 0 | N7: =IFERROR(VLOOKUP($A7,'[1]Donor-Served OBs'!A:N,4,0),0) -> 0 | O7: =ROUNDUP(IF(A7=0,0,IFERROR(VLOOKUP($A7,'[1]Donor''s Assigned Kilos'!A:O,4,0),0)),0) -> 0 | P7: =IF(A7=0,0,IFERROR(SUMIFS([1]Population!N:N,[1]Population!J:J,'MASTER-2025'!A7),0)) -> 0 | Q7: =IFERROR(VLOOKUP($A7,'[1]Donor-Served OBs'!A:N,2,0),0) -> 0 | R7: =ROUNDUP(ROUND(IF(A7=0,0,IFERROR(VLOOKUP($A7,'[1]Donor''s Assigned Kilos'!A:O,9,0),0)),1),0) -> 0 | S7: =IF(A7=0,0,IFERROR(SUMIFS([1]Population!S:S,[1]Population!J:J,'MASTER-2025'!A7),0)) -> 0 | T7: =IFERROR(VLOOKUP($A7,'[1]Donor-Served OBs'!A:N,12,0),0) -> 0 | U7: =ROUNDUP(IF(A7=0,0,IF(A7=0,0,IFERROR(VLOOKUP($A7,'[1]Donor''s Assigned Kilos'!A:O,7,0),0))),0) -> 0 | V7: =IF(A7=0,0,IFERROR(SUMIFS([1]Population!Q:Q,[1]Population!J:J,'MASTER-2025'!A7),0)) -> 0 | W7: =IFERROR(VLOOKUP($A7,'[1]Donor-Served OBs'!A:N,10,0),0) -> 0 | X7: =ROUNDUP(IF(A7=0,0,IFERROR(VLOOKUP($A7,'[1]Donor''s Assigned Kilos'!A:N,5,0),0)),0) -> 0 | Y7: =IF(A7=0,0,IFERROR(SUMIFS([1]Population!O:O,[1]Population!J:J,'MASTER-2025'!A7),0)) -> 0 | Z7: =IFERROR(VLOOKUP($A7,'[1]Donor-Served OBs'!A:N,6,0),0) -> 0 | AA7: =ROUNDUP(IF(A7=0,0,IFERROR(VLOOKUP($A7,'[1]Donor''s Assigned Kilos'!A:N,11,0),0)),0) -> 0 | AB7: =IF(A7=0,0,IFERROR(SUMIFS([1]Population!U:U,[1]Population!J:J,'MASTER-2025'!A7),0)) -> 0 | AC7: =IFERROR(VLOOKUP($A7,'[1]Donor-Served OBs'!A:N,7,0),0) -> 0 | AD7: =ROUNDUP(IF(A7=0,0,IFERROR(VLOOKUP($A7,'[1]Donor''s Assigned Kilos'!A:N,8,0),0)),0) -> 0 | AE7: =IF(A7=0,0,IFERROR(SUMIFS([1]Population!R:R,[1]Population!J:J,'MASTER-2025'!A7),0)) -> 0 | AF7: =IFERROR(VLOOKUP($A7,'[1]Donor-Served OBs'!A:N,8,0),0) -> 0 | AG7: =ROUNDUP(IF(A7=0,0,IFERROR(VLOOKUP($A7,'[1]Donor''s Assigned Kilos'!A:N,6,0),0)),0) -> 0 | AH7: =IF(A7=0,0,IFERROR(SUMIFS([1]Population!P:P,[1]Population!J:J,'MASTER-2025'!A7),0)) -> 0 | AI7: =IFERROR(VLOOKUP($A7,'[1]Donor-Served OBs'!A:N,9,0),0) -> 0 | AJ7: =ROUNDUP(IF(A7=0,0,IFERROR(VLOOKUP($A7,'[1]Donor''s Assigned Kilos'!A:N,12,0),0)),0) -> 0 | AK7: =IF(A7=0,0,IFERROR(SUMIFS([1]Population!V:V,[1]Population!J:J,'MASTER-2025'!A7),0)) -> 0 | AL7: =IFERROR(VLOOKUP($A7,'[1]Donor-Served OBs'!A:N,16,0),0) -> 0 | AM7: =ROUNDUP(IF(A7=0,0,IFERROR(VLOOKUP($A7,'[1]Donor''s Assigned Kilos'!A:O,16,0),0)),0) -> 0 | AN7: =IF(A7=0,0,IFERROR(SUMIFS([1]Population!Z:Z,[1]Population!J:J,'MASTER-2025'!A7),0)) -> 0 | AO7: =IFERROR(VLOOKUP($A7,'[1]Donor-Served OBs'!A:N,11,0),0) -> 0 | AP7: =ROUNDUP(IF(A7=0,0,IFERROR(VLOOKUP($A7,'[1]Donor''s Assigned Kilos'!A:N,13,0),0)),0) -> 0 | AQ7: =IF(A7=0,0,IFERROR(SUMIFS([1]Population!W:W,[1]Population!J:J,'MASTER-2025'!A7),0)) -> 0 | AR7: =IFERROR(VLOOKUP($A7,'[1]Donor-Served OBs'!A:N,5,0),0) -> 0 | AS7: =ROUNDUP(IF(A7=0,0,IFERROR(VLOOKUP($A7,'[1]Donor''s Assigned Kilos'!A:N,10,0),0)),0) -> 0 | AT7: =IF(A7=0,0,IFERROR(SUMIFS([1]Population!T:T,[1]Population!J:J,'MASTER-2025'!A7),0)) -> 0 | AU7: =IFERROR(VLOOKUP($A7,'[1]Donor-Served OBs'!A:N,13,0),0) -> 0 | AV7: =ROUNDUP(IF(A7=0,0,IFERROR(VLOOKUP($A7,'[1]Donor''s Assigned Kilos'!A:N,14,0),0)),0) -> 0 | AW7: =IF(A7=0,0,IFERROR(SUMIFS([1]Population!X:X,[1]Population!J:J,'MASTER-2025'!A7),0)) -> 0 | AX7: =IFERROR(VLOOKUP($A7,'[1]Donor-Served OBs'!A:N,16,0),0) -> 0 | AY7: =ROUNDUP(IF(A7=0,0,IFERROR(VLOOKUP($A7,'[1]Donor''s Assigned Kilos'!A:O,16,0),0)),0) -> 0 | AZ7: =IF(A7=0,0,IFERROR(SUMIFS([1]Population!Y:Y,[1]Population!J:J,'MASTER-2025'!A7),0)) -> 0 | BA7: =+H7+K7+N7+Q7+T7+W7+Z7+AC7+AF7+AI7+AL7+AO7+AR7+AU7+AX7 -> 0 | BB7: =INT(I7+L7+O7+R7+U7+X7+AA7+AD7+AG7+AJ7+AM7+AP7+AS7+AV7+AY7) -> 0 | BC7: =ROUND(I7+L7+O7+R7+U7,0) -> 0 | BD7: =IF(A7=0,0,(+J7+M7+P7+S7+V7+Y7+AB7+AE7+AH7+AK7+AN7+AQ7+AT7+AW7+AZ7)) -> 0 | BE7: =IF(A7=0,0,SUMIFS([1]Population!C:C,[1]Population!A:A,'MASTER-2025'!A7)) -> #VALUE! | BF7: =IF(A7=0,0,SUMIFS([1]Population!D:D,[1]Population!A:A,'MASTER-2025'!A7)) -> #VALUE! | BG7: =IF(A7=0,0,SUMIFS([1]Population!E:E,[1]Population!A:A,'MASTER-2025'!A7)) -> #VALUE! | BH7: =IF(A7=0,0,SUMIFS([1]Population!F:F,[1]Population!A:A,'MASTER-2025'!A7)) -> #VALUE! | BI7: =+BF7+BG7+BH7 -> #VALUE! | BJ7: =+BK7-BI7-BH7-BG7-BF7-BE7 -> #VALUE! | BK7: =IF(A7=0,0,SUMIFS([1]Population!G:G,[1]Population!A:A,'MASTER-2025'!A7)) -> #VALUE! | BL7: {=IFERROR(VLOOKUP(A7,'[1]Now-OB-kg-POB-25'!A:AQ,{3,4,5,6,7,8,9,10,11,12,13,14},0),0)} -> 33 | BM7: 33 | BN7: 23 | BO7: 0 | BP7: 0 | BQ7: 0 | BR7: 0 | BS7: 0 | BT7: 0 | BU7: 0 | BV7: 0 | BW7: 0 | BX7: =SUM(BL7:BW7) -> 89 | BY7: {=IFERROR(VLOOKUP(A7,'[1]Now-OB-kg-POB-25'!A:AQ,{17,18,19,20,21,22,23,24,25,26,27,28},0),0)} -> 678 | BZ7: 663 | CA7: 663 | CB7: 0 | CC7: 0 | CD7: 0 | CE7: 0 | CF7: 0 | CG7: 0 | CH7: 0 | CI7: 0 | CJ7: 0 | CK7: =SUM(BY7:CJ7) -> 2004 | CL7: {=IFERROR(VLOOKUP(A7,'[1]Now-OB-kg-POB-25'!A:AQ,{31,32,33,34,35,36,37,38,39,40,41,42},0),0)} -> 14845 | CM7: 8298 | CN7: 6241 | CO7: 0 | CP7: 0 | CQ7: 0 | CR7: 0 | CS7: 0 | CT7: 0 | CU7: 0 | CV7: 0 | CW7: 0 | CX7: =SUM(CL7:CW7) -> 29384 | CY7: =IF(A7=0,0,IFERROR(VLOOKUP(A7,'[1]Info Donantes'!C:F,2,0),"Sin Contacto")) -> Sin Contacto | CZ7: =IF(A7=0,0,IFERROR(VLOOKUP(A7,'[1]Info Donantes'!C:F,3,0),"Sin Correo")) -> Sin Correo | DA7: =IF(A7=0,0,IFERROR(VLOOKUP(A7,'[1]Info Donantes'!C:F,4,0),"Sin Telefono")) -> Sin Telefono | DB7: Traceability Report - - KOL SHEARITH ISRAEL BROTHERHOOD CONGREGATION
A8: CORPORACIÓN INTERNACIONAL DE ALIMENTOS, S.A. | B8: =INT(IFERROR(VLOOKUP(A8,'[1]Donor Summary'!C:F,3,0),0)) -> 0 | C8: =INT(ROUND(IFERROR(VLOOKUP(A8,'[1]Donor Summary'!C:F,4,0),0),1)) -> 0 | D8: =INT(ROUND(C8-B8,1)) -> 0 | E8: =IF(A8=0,"",TEXT((IFERROR(D8/C8,0)),"0.00%")) -> 0.00% | F8: =IF(A8=0,"",TEXT((IFERROR(B8/C8,0)),"0.0%")) -> 0.0% | G8: =INT(D8*3) -> 0 | I8: =IFERROR(VLOOKUP(A8,'[1]Lot All by Part'!T:Y,6,0),0) -> 0 | K8: =IFERROR(VLOOKUP($A8,'[1]Donor-Served OBs'!A:N,3,0),0) -> 0 | L8: =ROUNDUP(IF(A8=0,0,IFERROR(VLOOKUP($A8,'[1]Donor''s Assigned Kilos'!A:O,3,0),0)),0) -> 0 | M8: =IF(A8=0,0,IFERROR(SUMIFS([1]Population!M:M,[1]Population!J:J,'MASTER-2025'!A8),0)) -> 0 | N8: =IFERROR(VLOOKUP($A8,'[1]Donor-Served OBs'!A:N,4,0),0) -> 0 | O8: =ROUNDUP(IF(A8=0,0,IFERROR(VLOOKUP($A8,'[1]Donor''s Assigned Kilos'!A:O,4,0),0)),0) -> 0 | P8: =IF(A8=0,0,IFERROR(SUMIFS([1]Population!N:N,[1]Population!J:J,'MASTER-2025'!A8),0)) -> 0 | Q8: =IFERROR(VLOOKUP($A8,'[1]Donor-Served OBs'!A:N,2,0),0) -> 0 | R8: =ROUNDUP(ROUND(IF(A8=0,0,IFERROR(VLOOKUP($A8,'[1]Donor''s Assigned Kilos'!A:O,9,0),0)),1),0) -> 0 | S8: =IF(A8=0,0,IFERROR(SUMIFS([1]Population!S:S,[1]Population!J:J,'MASTER-2025'!A8),0)) -> 0 | T8: =IFERROR(VLOOKUP($A8,'[1]Donor-Served OBs'!A:N,12,0),0) -> 0 | U8: =ROUNDUP(IF(A8=0,0,IF(A8=0,0,IFERROR(VLOOKUP($A8,'[1]Donor''s Assigned Kilos'!A:O,7,0),0))),0) -> 0 | V8: =IF(A8=0,0,IFERROR(SUMIFS([1]Population!Q:Q,[1]Population!J:J,'MASTER-2025'!A8),0)) -> 0 | W8: =IFERROR(VLOOKUP($A8,'[1]Donor-Served OBs'!A:N,10,0),0) -> 0 | X8: =ROUNDUP(IF(A8=0,0,IFERROR(VLOOKUP($A8,'[1]Donor''s Assigned Kilos'!A:N,5,0),0)),0) -> 0 | Y8: =IF(A8=0,0,IFERROR(SUMIFS([1]Population!O:O,[1]Population!J:J,'MASTER-2025'!A8),0)) -> 0 | Z8: =IFERROR(VLOOKUP($A8,'[1]Donor-Served OBs'!A:N,6,0),0) -> 0 | AA8: =ROUNDUP(IF(A8=0,0,IFERROR(VLOOKUP($A8,'[1]Donor''s Assigned Kilos'!A:N,11,0),0)),0) -> 0 | AB8: =IF(A8=0,0,IFERROR(SUMIFS([1]Population!U:U,[1]Population!J:J,'MASTER-2025'!A8),0)) -> 0 | AC8: =IFERROR(VLOOKUP($A8,'[1]Donor-Served OBs'!A:N,7,0),0) -> 0 | AD8: =ROUNDUP(IF(A8=0,0,IFERROR(VLOOKUP($A8,'[1]Donor''s Assigned Kilos'!A:N,8,0),0)),0) -> 0 | AE8: =IF(A8=0,0,IFERROR(SUMIFS([1]Population!R:R,[1]Population!J:J,'MASTER-2025'!A8),0)) -> 0 | AF8: =IFERROR(VLOOKUP($A8,'[1]Donor-Served OBs'!A:N,8,0),0) -> 0 | AG8: =ROUNDUP(IF(A8=0,0,IFERROR(VLOOKUP($A8,'[1]Donor''s Assigned Kilos'!A:N,6,0),0)),0) -> 0 | AH8: =IF(A8=0,0,IFERROR(SUMIFS([1]Population!P:P,[1]Population!J:J,'MASTER-2025'!A8),0)) -> 0 | AI8: =IFERROR(VLOOKUP($A8,'[1]Donor-Served OBs'!A:N,9,0),0) -> 0 | AJ8: =ROUNDUP(IF(A8=0,0,IFERROR(VLOOKUP($A8,'[1]Donor''s Assigned Kilos'!A:N,12,0),0)),0) -> 0 | AK8: =IF(A8=0,0,IFERROR(SUMIFS([1]Population!V:V,[1]Population!J:J,'MASTER-2025'!A8),0)) -> 0 | AL8: =IFERROR(VLOOKUP($A8,'[1]Donor-Served OBs'!A:N,16,0),0) -> 0 | AM8: =ROUNDUP(IF(A8=0,0,IFERROR(VLOOKUP($A8,'[1]Donor''s Assigned Kilos'!A:O,16,0),0)),0) -> 0 | AN8: =IF(A8=0,0,IFERROR(SUMIFS([1]Population!Z:Z,[1]Population!J:J,'MASTER-2025'!A8),0)) -> 0 | AO8: =IFERROR(VLOOKUP($A8,'[1]Donor-Served OBs'!A:N,11,0),0) -> 0 | AP8: =ROUNDUP(IF(A8=0,0,IFERROR(VLOOKUP($A8,'[1]Donor''s Assigned Kilos'!A:N,13,0),0)),0) -> 0 | AQ8: =IF(A8=0,0,IFERROR(SUMIFS([1]Population!W:W,[1]Population!J:J,'MASTER-2025'!A8),0)) -> 0 | AR8: =IFERROR(VLOOKUP($A8,'[1]Donor-Served OBs'!A:N,5,0),0) -> 0 | AS8: =ROUNDUP(IF(A8=0,0,IFERROR(VLOOKUP($A8,'[1]Donor''s Assigned Kilos'!A:N,10,0),0)),0) -> 0 | AT8: =IF(A8=0,0,IFERROR(SUMIFS([1]Population!T:T,[1]Population!J:J,'MASTER-2025'!A8),0)) -> 0 | AU8: =IFERROR(VLOOKUP($A8,'[1]Donor-Served OBs'!A:N,13,0),0) -> 0 | AV8: =ROUNDUP(IF(A8=0,0,IFERROR(VLOOKUP($A8,'[1]Donor''s Assigned Kilos'!A:N,14,0),0)),0) -> 0 | AW8: =IF(A8=0,0,IFERROR(SUMIFS([1]Population!X:X,[1]Population!J:J,'MASTER-2025'!A8),0)) -> 0 | AX8: =IFERROR(VLOOKUP($A8,'[1]Donor-Served OBs'!A:N,16,0),0) -> 0 | AY8: =ROUNDUP(IF(A8=0,0,IFERROR(VLOOKUP($A8,'[1]Donor''s Assigned Kilos'!A:O,16,0),0)),0) -> 0 | AZ8: =IF(A8=0,0,IFERROR(SUMIFS([1]Population!Y:Y,[1]Population!J:J,'MASTER-2025'!A8),0)) -> 0 | BA8: =+H8+K8+N8+Q8+T8+W8+Z8+AC8+AF8+AI8+AL8+AO8+AR8+AU8+AX8 -> 0 | BB8: =INT(I8+L8+O8+R8+U8+X8+AA8+AD8+AG8+AJ8+AM8+AP8+AS8+AV8+AY8) -> 0 | BC8: =ROUND(I8+L8+O8+R8+U8,0) -> 0 | BD8: =IF(A8=0,0,(+J8+M8+P8+S8+V8+Y8+AB8+AE8+AH8+AK8+AN8+AQ8+AT8+AW8+AZ8)) -> 0 | BE8: =IF(A8=0,0,SUMIFS([1]Population!C:C,[1]Population!A:A,'MASTER-2025'!A8)) -> #VALUE! | BF8: =IF(A8=0,0,SUMIFS([1]Population!D:D,[1]Population!A:A,'MASTER-2025'!A8)) -> #VALUE! | BG8: =IF(A8=0,0,SUMIFS([1]Population!E:E,[1]Population!A:A,'MASTER-2025'!A8)) -> #VALUE! | BH8: =IF(A8=0,0,SUMIFS([1]Population!F:F,[1]Population!A:A,'MASTER-2025'!A8)) -> #VALUE! | BI8: =+BF8+BG8+BH8 -> #VALUE! | BJ8: =+BK8-BI8-BH8-BG8-BF8-BE8 -> #VALUE! | BK8: =IF(A8=0,0,SUMIFS([1]Population!G:G,[1]Population!A:A,'MASTER-2025'!A8)) -> #VALUE! | BL8: {=IFERROR(VLOOKUP(A8,'[1]Now-OB-kg-POB-25'!A:AQ,{3,4,5,6,7,8,9,10,11,12,13,14},0),0)} -> 100 | BM8: 117 | BN8: 148 | BO8: 0 | BP8: 0 | BQ8: 0 | BR8: 0 | BS8: 0 | BT8: 0 | BU8: 0 | BV8: 0 | BW8: 0 | BX8: =SUM(BL8:BW8) -> 365 | BY8: {=IFERROR(VLOOKUP(A8,'[1]Now-OB-kg-POB-25'!A:AQ,{17,18,19,20,21,22,23,24,25,26,27,28},0),0)} -> 26159 | BZ8: 21470 | CA8: 60995 | CB8: 0 | CC8: 0 | CD8: 0 | CE8: 0 | CF8: 0 | CG8: 0 | CH8: 0 | CI8: 0 | CJ8: 0 | CK8: =SUM(BY8:CJ8) -> 108624 | CL8: {=IFERROR(VLOOKUP(A8,'[1]Now-OB-kg-POB-25'!A:AQ,{31,32,33,34,35,36,37,38,39,40,41,42},0),0)} -> 33000 | CM8: 35637 | CN8: 44724 | CO8: 0 | CP8: 0 | CQ8: 0 | CR8: 0 | CS8: 0 | CT8: 0 | CU8: 0 | CV8: 0 | CW8: 0 | CX8: =SUM(CL8:CW8) -> 113361 | CY8: =IF(A8=0,0,IFERROR(VLOOKUP(A8,'[1]Info Donantes'!C:F,2,0),"Sin Contacto")) -> Sin Contacto | CZ8: =IF(A8=0,0,IFERROR(VLOOKUP(A8,'[1]Info Donantes'!C:F,3,0),"Sin Correo")) -> Sin Correo | DA8: =IF(A8=0,0,IFERROR(VLOOKUP(A8,'[1]Info Donantes'!C:F,4,0),"Sin Telefono")) -> Sin Telefono | DB8: Traceability Report - - CORPORACIÓN INTERNACIONAL DE ALIMENTOS, S.A.
A9: Delivery Hero Dmart Panama S.A. (Orders Now) | B9: =INT(IFERROR(VLOOKUP(A9,'[1]Donor Summary'!C:F,3,0),0)) -> 0 | C9: =INT(ROUND(IFERROR(VLOOKUP(A9,'[1]Donor Summary'!C:F,4,0),0),1)) -> 0 | D9: =INT(ROUND(C9-B9,1)) -> 0 | E9: =IF(A9=0,"",TEXT((IFERROR(D9/C9,0)),"0.00%")) -> 0.00% | F9: =IF(A9=0,"",TEXT((IFERROR(B9/C9,0)),"0.0%")) -> 0.0% | G9: =INT(D9*3) -> 0 | I9: =IFERROR(VLOOKUP(A9,'[1]Lot All by Part'!T:Y,6,0),0) -> 0 | K9: =IFERROR(VLOOKUP($A9,'[1]Donor-Served OBs'!A:N,3,0),0) -> 0 | L9: =ROUNDUP(IF(A9=0,0,IFERROR(VLOOKUP($A9,'[1]Donor''s Assigned Kilos'!A:O,3,0),0)),0) -> 0 | M9: =IF(A9=0,0,IFERROR(SUMIFS([1]Population!M:M,[1]Population!J:J,'MASTER-2025'!A9),0)) -> 0 | N9: =IFERROR(VLOOKUP($A9,'[1]Donor-Served OBs'!A:N,4,0),0) -> 0 | O9: =ROUNDUP(IF(A9=0,0,IFERROR(VLOOKUP($A9,'[1]Donor''s Assigned Kilos'!A:O,4,0),0)),0) -> 0 | P9: =IF(A9=0,0,IFERROR(SUMIFS([1]Population!N:N,[1]Population!J:J,'MASTER-2025'!A9),0)) -> 0 | Q9: =IFERROR(VLOOKUP($A9,'[1]Donor-Served OBs'!A:N,2,0),0) -> 0 | R9: =ROUNDUP(ROUND(IF(A9=0,0,IFERROR(VLOOKUP($A9,'[1]Donor''s Assigned Kilos'!A:O,9,0),0)),1),0) -> 0 | S9: =IF(A9=0,0,IFERROR(SUMIFS([1]Population!S:S,[1]Population!J:J,'MASTER-2025'!A9),0)) -> 0 | T9: =IFERROR(VLOOKUP($A9,'[1]Donor-Served OBs'!A:N,12,0),0) -> 0 | U9: =ROUNDUP(IF(A9=0,0,IF(A9=0,0,IFERROR(VLOOKUP($A9,'[1]Donor''s Assigned Kilos'!A:O,7,0),0))),0) -> 0 | V9: =IF(A9=0,0,IFERROR(SUMIFS([1]Population!Q:Q,[1]Population!J:J,'MASTER-2025'!A9),0)) -> 0 | W9: =IFERROR(VLOOKUP($A9,'[1]Donor-Served OBs'!A:N,10,0),0) -> 0 | X9: =ROUNDUP(IF(A9=0,0,IFERROR(VLOOKUP($A9,'[1]Donor''s Assigned Kilos'!A:N,5,0),0)),0) -> 0 | Y9: =IF(A9=0,0,IFERROR(SUMIFS([1]Population!O:O,[1]Population!J:J,'MASTER-2025'!A9),0)) -> 0 | Z9: =IFERROR(VLOOKUP($A9,'[1]Donor-Served OBs'!A:N,6,0),0) -> 0 | AA9: =ROUNDUP(IF(A9=0,0,IFERROR(VLOOKUP($A9,'[1]Donor''s Assigned Kilos'!A:N,11,0),0)),0) -> 0 | AB9: =IF(A9=0,0,IFERROR(SUMIFS([1]Population!U:U,[1]Population!J:J,'MASTER-2025'!A9),0)) -> 0 | AC9: =IFERROR(VLOOKUP($A9,'[1]Donor-Served OBs'!A:N,7,0),0) -> 0 | AD9: =ROUNDUP(IF(A9=0,0,IFERROR(VLOOKUP($A9,'[1]Donor''s Assigned Kilos'!A:N,8,0),0)),0) -> 0 | AE9: =IF(A9=0,0,IFERROR(SUMIFS([1]Population!R:R,[1]Population!J:J,'MASTER-2025'!A9),0)) -> 0 | AF9: =IFERROR(VLOOKUP($A9,'[1]Donor-Served OBs'!A:N,8,0),0) -> 0 | AG9: =ROUNDUP(IF(A9=0,0,IFERROR(VLOOKUP($A9,'[1]Donor''s Assigned Kilos'!A:N,6,0),0)),0) -> 0 | AH9: =IF(A9=0,0,IFERROR(SUMIFS([1]Population!P:P,[1]Population!J:J,'MASTER-2025'!A9),0)) -> 0 | AI9: =IFERROR(VLOOKUP($A9,'[1]Donor-Served OBs'!A:N,9,0),0) -> 0 | AJ9: =ROUNDUP(IF(A9=0,0,IFERROR(VLOOKUP($A9,'[1]Donor''s Assigned Kilos'!A:N,12,0),0)),0) -> 0 | AK9: =IF(A9=0,0,IFERROR(SUMIFS([1]Population!V:V,[1]Population!J:J,'MASTER-2025'!A9),0)) -> 0 | AL9: =IFERROR(VLOOKUP($A9,'[1]Donor-Served OBs'!A:N,16,0),0) -> 0 | AM9: =ROUNDUP(IF(A9=0,0,IFERROR(VLOOKUP($A9,'[1]Donor''s Assigned Kilos'!A:O,16,0),0)),0) -> 0 | AN9: =IF(A9=0,0,IFERROR(SUMIFS([1]Population!Z:Z,[1]Population!J:J,'MASTER-2025'!A9),0)) -> 0 | AO9: =IFERROR(VLOOKUP($A9,'[1]Donor-Served OBs'!A:N,11,0),0) -> 0 | AP9: =ROUNDUP(IF(A9=0,0,IFERROR(VLOOKUP($A9,'[1]Donor''s Assigned Kilos'!A:N,13,0),0)),0) -> 0 | AQ9: =IF(A9=0,0,IFERROR(SUMIFS([1]Population!W:W,[1]Population!J:J,'MASTER-2025'!A9),0)) -> 0 | AR9: =IFERROR(VLOOKUP($A9,'[1]Donor-Served OBs'!A:N,5,0),0) -> 0 | AS9: =ROUNDUP(IF(A9=0,0,IFERROR(VLOOKUP($A9,'[1]Donor''s Assigned Kilos'!A:N,10,0),0)),0) -> 0 | AT9: =IF(A9=0,0,IFERROR(SUMIFS([1]Population!T:T,[1]Population!J:J,'MASTER-2025'!A9),0)) -> 0 | AU9: =IFERROR(VLOOKUP($A9,'[1]Donor-Served OBs'!A:N,13,0),0) -> 0 | AV9: =ROUNDUP(IF(A9=0,0,IFERROR(VLOOKUP($A9,'[1]Donor''s Assigned Kilos'!A:N,14,0),0)),0) -> 0 | AW9: =IF(A9=0,0,IFERROR(SUMIFS([1]Population!X:X,[1]Population!J:J,'MASTER-2025'!A9),0)) -> 0 | AX9: =IFERROR(VLOOKUP($A9,'[1]Donor-Served OBs'!A:N,16,0),0) -> 0 | AY9: =ROUNDUP(IF(A9=0,0,IFERROR(VLOOKUP($A9,'[1]Donor''s Assigned Kilos'!A:O,16,0),0)),0) -> 0 | AZ9: =IF(A9=0,0,IFERROR(SUMIFS([1]Population!Y:Y,[1]Population!J:J,'MASTER-2025'!A9),0)) -> 0 | BA9: =+H9+K9+N9+Q9+T9+W9+Z9+AC9+AF9+AI9+AL9+AO9+AR9+AU9+AX9 -> 0 | BB9: =INT(I9+L9+O9+R9+U9+X9+AA9+AD9+AG9+AJ9+AM9+AP9+AS9+AV9+AY9) -> 0 | BC9: =ROUND(I9+L9+O9+R9+U9,0) -> 0 | BD9: =IF(A9=0,0,(+J9+M9+P9+S9+V9+Y9+AB9+AE9+AH9+AK9+AN9+AQ9+AT9+AW9+AZ9)) -> 0 | BE9: =IF(A9=0,0,SUMIFS([1]Population!C:C,[1]Population!A:A,'MASTER-2025'!A9)) -> #VALUE! | BF9: =IF(A9=0,0,SUMIFS([1]Population!D:D,[1]Population!A:A,'MASTER-2025'!A9)) -> #VALUE! | BG9: =IF(A9=0,0,SUMIFS([1]Population!E:E,[1]Population!A:A,'MASTER-2025'!A9)) -> #VALUE! | BH9: =IF(A9=0,0,SUMIFS([1]Population!F:F,[1]Population!A:A,'MASTER-2025'!A9)) -> #VALUE! | BI9: =+BF9+BG9+BH9 -> #VALUE! | BJ9: =+BK9-BI9-BH9-BG9-BF9-BE9 -> #VALUE! | BK9: =IF(A9=0,0,SUMIFS([1]Population!G:G,[1]Population!A:A,'MASTER-2025'!A9)) -> #VALUE! | BL9: {=IFERROR(VLOOKUP(A9,'[1]Now-OB-kg-POB-25'!A:AQ,{3,4,5,6,7,8,9,10,11,12,13,14},0),0)} -> 24 | BM9: 30 | BN9: 26 | BO9: 0 | BP9: 0 | BQ9: 0 | BR9: 0 | BS9: 0 | BT9: 0 | BU9: 0 | BV9: 0 | BW9: 0 | BX9: =SUM(BL9:BW9) -> 80 | BY9: {=IFERROR(VLOOKUP(A9,'[1]Now-OB-kg-POB-25'!A:AQ,{17,18,19,20,21,22,23,24,25,26,27,28},0),0)} -> 242 | BZ9: 384 | CA9: 334 | CB9: 0 | CC9: 0 | CD9: 0 | CE9: 0 | CF9: 0 | CG9: 0 | CH9: 0 | CI9: 0 | CJ9: 0 | CK9: =SUM(BY9:CJ9) -> 960 | CL9: {=IFERROR(VLOOKUP(A9,'[1]Now-OB-kg-POB-25'!A:AQ,{31,32,33,34,35,36,37,38,39,40,41,42},0),0)} -> 7458 | CM9: 7006 | CN9: 7257 | CO9: 0 | CP9: 0 | CQ9: 0 | CR9: 0 | CS9: 0 | CT9: 0 | CU9: 0 | CV9: 0 | CW9: 0 | CX9: =SUM(CL9:CW9) -> 21721 | CY9: =IF(A9=0,0,IFERROR(VLOOKUP(A9,'[1]Info Donantes'!C:F,2,0),"Sin Contacto")) -> Sin Contacto | CZ9: =IF(A9=0,0,IFERROR(VLOOKUP(A9,'[1]Info Donantes'!C:F,3,0),"Sin Correo")) -> Sin Correo | DA9: =IF(A9=0,0,IFERROR(VLOOKUP(A9,'[1]Info Donantes'!C:F,4,0),"Sin Telefono")) -> Sin Telefono | DB9: Traceability Report - - Delivery Hero Dmart Panama S.A. (Orders Now)
A10: Empresa Panamaniña de Alimentos, S. A. | B10: =INT(IFERROR(VLOOKUP(A10,'[1]Donor Summary'!C:F,3,0),0)) -> 0 | C10: =INT(ROUND(IFERROR(VLOOKUP(A10,'[1]Donor Summary'!C:F,4,0),0),1)) -> 0 | D10: =INT(ROUND(C10-B10,1)) -> 0 | E10: =IF(A10=0,"",TEXT((IFERROR(D10/C10,0)),"0.00%")) -> 0.00% | F10: =IF(A10=0,"",TEXT((IFERROR(B10/C10,0)),"0.0%")) -> 0.0% | G10: =INT(D10*3) -> 0 | I10: =IFERROR(VLOOKUP(A10,'[1]Lot All by Part'!T:Y,6,0),0) -> 0 | K10: =IFERROR(VLOOKUP($A10,'[1]Donor-Served OBs'!A:N,3,0),0) -> 0 | L10: =ROUNDUP(IF(A10=0,0,IFERROR(VLOOKUP($A10,'[1]Donor''s Assigned Kilos'!A:O,3,0),0)),0) -> 0 | M10: =IF(A10=0,0,IFERROR(SUMIFS([1]Population!M:M,[1]Population!J:J,'MASTER-2025'!A10),0)) -> 0 | N10: =IFERROR(VLOOKUP($A10,'[1]Donor-Served OBs'!A:N,4,0),0) -> 0 | O10: =ROUNDUP(IF(A10=0,0,IFERROR(VLOOKUP($A10,'[1]Donor''s Assigned Kilos'!A:O,4,0),0)),0) -> 0 | P10: =IF(A10=0,0,IFERROR(SUMIFS([1]Population!N:N,[1]Population!J:J,'MASTER-2025'!A10),0)) -> 0 | Q10: =IFERROR(VLOOKUP($A10,'[1]Donor-Served OBs'!A:N,2,0),0) -> 0 | R10: =ROUNDUP(ROUND(IF(A10=0,0,IFERROR(VLOOKUP($A10,'[1]Donor''s Assigned Kilos'!A:O,9,0),0)),1),0) -> 0 | S10: =IF(A10=0,0,IFERROR(SUMIFS([1]Population!S:S,[1]Population!J:J,'MASTER-2025'!A10),0)) -> 0 | T10: =IFERROR(VLOOKUP($A10,'[1]Donor-Served OBs'!A:N,12,0),0) -> 0 | U10: =ROUNDUP(IF(A10=0,0,IF(A10=0,0,IFERROR(VLOOKUP($A10,'[1]Donor''s Assigned Kilos'!A:O,7,0),0))),0) -> 0 | V10: =IF(A10=0,0,IFERROR(SUMIFS([1]Population!Q:Q,[1]Population!J:J,'MASTER-2025'!A10),0)) -> 0 | W10: =IFERROR(VLOOKUP($A10,'[1]Donor-Served OBs'!A:N,10,0),0) -> 0 | X10: =ROUNDUP(IF(A10=0,0,IFERROR(VLOOKUP($A10,'[1]Donor''s Assigned Kilos'!A:N,5,0),0)),0) -> 0 | Y10: =IF(A10=0,0,IFERROR(SUMIFS([1]Population!O:O,[1]Population!J:J,'MASTER-2025'!A10),0)) -> 0 | Z10: =IFERROR(VLOOKUP($A10,'[1]Donor-Served OBs'!A:N,6,0),0) -> 0 | AA10: =ROUNDUP(IF(A10=0,0,IFERROR(VLOOKUP($A10,'[1]Donor''s Assigned Kilos'!A:N,11,0),0)),0) -> 0 | AB10: =IF(A10=0,0,IFERROR(SUMIFS([1]Population!U:U,[1]Population!J:J,'MASTER-2025'!A10),0)) -> 0 | AC10: =IFERROR(VLOOKUP($A10,'[1]Donor-Served OBs'!A:N,7,0),0) -> 0 | AD10: =ROUNDUP(IF(A10=0,0,IFERROR(VLOOKUP($A10,'[1]Donor''s Assigned Kilos'!A:N,8,0),0)),0) -> 0 | AE10: =IF(A10=0,0,IFERROR(SUMIFS([1]Population!R:R,[1]Population!J:J,'MASTER-2025'!A10),0)) -> 0 | AF10: =IFERROR(VLOOKUP($A10,'[1]Donor-Served OBs'!A:N,8,0),0) -> 0 | AG10: =ROUNDUP(IF(A10=0,0,IFERROR(VLOOKUP($A10,'[1]Donor''s Assigned Kilos'!A:N,6,0),0)),0) -> 0 | AH10: =IF(A10=0,0,IFERROR(SUMIFS([1]Population!P:P,[1]Population!J:J,'MASTER-2025'!A10),0)) -> 0 | AI10: =IFERROR(VLOOKUP($A10,'[1]Donor-Served OBs'!A:N,9,0),0) -> 0 | AJ10: =ROUNDUP(IF(A10=0,0,IFERROR(VLOOKUP($A10,'[1]Donor''s Assigned Kilos'!A:N,12,0),0)),0) -> 0 | AK10: =IF(A10=0,0,IFERROR(SUMIFS([1]Population!V:V,[1]Population!J:J,'MASTER-2025'!A10),0)) -> 0 | AL10: =IFERROR(VLOOKUP($A10,'[1]Donor-Served OBs'!A:N,16,0),0) -> 0 | AM10: =ROUNDUP(IF(A10=0,0,IFERROR(VLOOKUP($A10,'[1]Donor''s Assigned Kilos'!A:O,16,0),0)),0) -> 0 | AN10: =IF(A10=0,0,IFERROR(SUMIFS([1]Population!Z:Z,[1]Population!J:J,'MASTER-2025'!A10),0)) -> 0 | AO10: =IFERROR(VLOOKUP($A10,'[1]Donor-Served OBs'!A:N,11,0),0) -> 0 | AP10: =ROUNDUP(IF(A10=0,0,IFERROR(VLOOKUP($A10,'[1]Donor''s Assigned Kilos'!A:N,13,0),0)),0) -> 0 | AQ10: =IF(A10=0,0,IFERROR(SUMIFS([1]Population!W:W,[1]Population!J:J,'MASTER-2025'!A10),0)) -> 0 | AR10: =IFERROR(VLOOKUP($A10,'[1]Donor-Served OBs'!A:N,5,0),0) -> 0 | AS10: =ROUNDUP(IF(A10=0,0,IFERROR(VLOOKUP($A10,'[1]Donor''s Assigned Kilos'!A:N,10,0),0)),0) -> 0 | AT10: =IF(A10=0,0,IFERROR(SUMIFS([1]Population!T:T,[1]Population!J:J,'MASTER-2025'!A10),0)) -> 0 | AU10: =IFERROR(VLOOKUP($A10,'[1]Donor-Served OBs'!A:N,13,0),0) -> 0 | AV10: =ROUNDUP(IF(A10=0,0,IFERROR(VLOOKUP($A10,'[1]Donor''s Assigned Kilos'!A:N,14,0),0)),0) -> 0 | AW10: =IF(A10=0,0,IFERROR(SUMIFS([1]Population!X:X,[1]Population!J:J,'MASTER-2025'!A10),0)) -> 0 | AX10: =IFERROR(VLOOKUP($A10,'[1]Donor-Served OBs'!A:N,16,0),0) -> 0 | AY10: =ROUNDUP(IF(A10=0,0,IFERROR(VLOOKUP($A10,'[1]Donor''s Assigned Kilos'!A:O,16,0),0)),0) -> 0 | AZ10: =IF(A10=0,0,IFERROR(SUMIFS([1]Population!Y:Y,[1]Population!J:J,'MASTER-2025'!A10),0)) -> 0 | BA10: =+H10+K10+N10+Q10+T10+W10+Z10+AC10+AF10+AI10+AL10+AO10+AR10+AU10+AX10 -> 0 | BB10: =INT(I10+L10+O10+R10+U10+X10+AA10+AD10+AG10+AJ10+AM10+AP10+AS10+AV10+AY10) -> 0 | BC10: =ROUND(I10+L10+O10+R10+U10,0) -> 0 | BD10: =IF(A10=0,0,(+J10+M10+P10+S10+V10+Y10+AB10+AE10+AH10+AK10+AN10+AQ10+AT10+AW10+AZ10)) -> 0 | BE10: =IF(A10=0,0,SUMIFS([1]Population!C:C,[1]Population!A:A,'MASTER-2025'!A10)) -> #VALUE! | BF10: =IF(A10=0,0,SUMIFS([1]Population!D:D,[1]Population!A:A,'MASTER-2025'!A10)) -> #VALUE! | BG10: =IF(A10=0,0,SUMIFS([1]Population!E:E,[1]Population!A:A,'MASTER-2025'!A10)) -> #VALUE! | BH10: =IF(A10=0,0,SUMIFS([1]Population!F:F,[1]Population!A:A,'MASTER-2025'!A10)) -> #VALUE! | BI10: =+BF10+BG10+BH10 -> #VALUE! | BJ10: =+BK10-BI10-BH10-BG10-BF10-BE10 -> #VALUE! | BK10: =IF(A10=0,0,SUMIFS([1]Population!G:G,[1]Population!A:A,'MASTER-2025'!A10)) -> #VALUE! | BL10: {=IFERROR(VLOOKUP(A10,'[1]Now-OB-kg-POB-25'!A:AQ,{3,4,5,6,7,8,9,10,11,12,13,14},0),0)} -> 42 | BM10: 87 | BN10: 111 | BO10: 0 | BP10: 0 | BQ10: 0 | BR10: 0 | BS10: 0 | BT10: 0 | BU10: 0 | BV10: 0 | BW10: 0 | BX10: =SUM(BL10:BW10) -> 240 | BY10: {=IFERROR(VLOOKUP(A10,'[1]Now-OB-kg-POB-25'!A:AQ,{17,18,19,20,21,22,23,24,25,26,27,28},0),0)} -> 6842 | BZ10: 5690 | CA10: 6413 | CB10: 0 | CC10: 0 | CD10: 0 | CE10: 0 | CF10: 0 | CG10: 0 | CH10: 0 | CI10: 0 | CJ10: 0 | CK10: =SUM(BY10:CJ10) -> 18945 | CL10: {=IFERROR(VLOOKUP(A10,'[1]Now-OB-kg-POB-25'!A:AQ,{31,32,33,34,35,36,37,38,39,40,41,42},0),0)} -> 14846 | CM10: 24125 | CN10: 31867 | CO10: 0 | CP10: 0 | CQ10: 0 | CR10: 0 | CS10: 0 | CT10: 0 | CU10: 0 | CV10: 0 | CW10: 0 | CX10: =SUM(CL10:CW10) -> 70838 | CY10: =IF(A10=0,0,IFERROR(VLOOKUP(A10,'[1]Info Donantes'!C:F,2,0),"Sin Contacto")) -> Sin Contacto | CZ10: =IF(A10=0,0,IFERROR(VLOOKUP(A10,'[1]Info Donantes'!C:F,3,0),"Sin Correo")) -> Sin Correo | DA10: =IF(A10=0,0,IFERROR(VLOOKUP(A10,'[1]Info Donantes'!C:F,4,0),"Sin Telefono")) -> Sin Telefono | DB10: Traceability Report - - Empresa Panamaniña de Alimentos, S. A.
